Workbook

Sheet Pipeline Summary
A1: WAIFF India Edition — Outreach Pipeline Summary
A2: Live dashboard, pulled from Targets / Gmail Tracker / LinkedIn Tracker. Update the two blue input cells; everything else recalculates.
A4: SENDING RAMP
A5: Campaign start date | B5: 46265
A6: Days into campaign (today) | B6: =IF($B$5="","",TODAY()-$B$5+1)
A7: Today's daily send target | B7: =IF($B$5="","",IF((TODAY()-$B$5+1)<=3,25,IF((TODAY()-$B$5+1)<=7,60,IF((TODAY()-$B$5+1)<=14,75,100))))
A8: Note (3 Sep 2026): ramp started mid-sequence — Aditya was already sending from his own Gmail, so days 1-3 were skipped. Days 4-7 bumped to 60/day (from the brief's default 50). Days 8-14 and 15+ continue on the original 75 / 100 schedule.
A9: Ramp reference (brief section 8)
A10: Days | B10: Sends/day
A11: Days 1-3 | B11: 25
A12: Days 4-7 | B12: 60
A13: Days 8-14 | B13: 75
A14: Days 15+ | B14: 100
A16: PIPELINE COUNTS (from Targets tab)
A17: Total companies logged | B17: =COUNTA(Targets!$A$5:$A$2000)
A18: Excluded (section 4) | B18: =COUNTIF(Targets!$O$5:$O$2000,"Excluded")
A19: Not started | B19: =COUNTIF(Targets!$O$5:$O$2000,"Not started")
A20: Researching | B20: =COUNTIF(Targets!$O$5:$O$2000,"Researching")
A21: Ready to send | B21: =COUNTIF(Targets!$O$5:$O$2000,"Ready to send")
A22: Sent | B22: =COUNTIF(Targets!$O$5:$O$2000,"Sent")
A23: Replied | B23: =COUNTIF(Targets!$O$5:$O$2000,"Replied")
A24: Meeting booked | B24: =COUNTIF(Targets!$O$5:$O$2000,"Meeting booked")
A25: Dormant (past day 25, no response) | B25: =COUNTIF(Targets!$O$5:$O$2000,"Dormant")
A27: EMAIL / FORM ACTIVITY (from Gmail Tracker tab)
A28: Total companies sent (email + form) | B28: =COUNTA('Gmail Tracker'!$A$5:$A$2000)
A29: Bounces | B29: =COUNTIF('Gmail Tracker'!$G$5:$G$2000,"Y")
A30: Bounce rate | B30: =IFERROR(B29/B28,"")
A31: Replies | B31: =COUNTIF('Gmail Tracker'!$H$5:$H$2000,"Y")
A32: Reply rate | B32: =IFERROR(B31/B28,"")
A33: Meetings booked | B33: =COUNTIF('Gmail Tracker'!$M$5:$M$2000,"Y")
A35: LINKEDIN ACTIVITY (from LinkedIn Tracker tab)
A36: Profiles logged (all batches) | B36: =COUNTA('LinkedIn Tracker'!$C$5:$C$2000)
A37: Connections sent | B37: =COUNTA('LinkedIn Tracker'!$H$5:$H$2000)
A38: Connections accepted | B38: =COUNTIF('LinkedIn Tracker'!$I$5:$I$2000,"Accepted")
A39: Accept rate | B39: =IFERROR(B38/B37,"")
A40: Messages sent | B40: =COUNTA('LinkedIn Tracker'!$J$5:$J$2000)
A41: Replies | B41: =COUNTIF('LinkedIn Tracker'!$K$5:$K$2000,"Y")
A43: 48-HOUR REVIEW (fill in manually every 2 days — brief section 10c)
A44: Date of review
A45: Best-performing segment
...

Sheet Targets
A1: WAIFF India — Targets (master company list, one row per company)
A2: One-pass rule: each company gets exactly one row. Check for duplicates and section-4 exclusions here before adding. Row 4 is an example only — real rows start at row 5.
A3: Company | B3: Priority Bucket | C3: HQ / Region | D3: Relevance (why qualified) | E3: Capacity check (Y/N/Unknown) | F3: Reachability - named contact found (Y/N) | G3: Excluded? (Y/N) | H3: Exclusion reason | I3: Role target (Sponsor/Organizer/Either) | J3: Best email address | K3: Other addresses (BCC) | L3: Enquiry form URL | M3: Channel chosen | N3: LinkedIn profiles logged? (Y/N) | O3: Status | P3: Date added | Q3: Date first contacted | R3: Follow-up Day 4 done (Y/N) | S3: Follow-up Day 11 done (Y/N) | T3: Follow-up Day 25 done (Y/N) | U3: Notes
A4: Runway AI, Inc. | B4: Venture-funded AI tool company | C4: New York, USA | D4: Makes AI video-generation tools used by filmmakers — direct category fit | E4: Y | F4: Y | G4: N | I4: Sponsor | J4: partnerships@runwayml.com | K4: press@runwayml.com | L4: https://runwayml.com/contact | M4: Email | N4: Y | O4: Researching | P4: 2026-09-03 | R4: N | S4: N | T4: N | U4: EXAMPLE ROW — edit or delete, do not count as real data
A5: Radisson Blu | D5: Already contacted directly by Aditya | E5: Unknown | F5: Unknown | G5: N | I5: Sponsor | J5: communication@radissonhotels.com | M5: Email | N5: N | O5: Replied | P5: 2026-09-01 | Q5: 2026-09-01 | R5: N | S5: N | T5: N | U5: Backfilled 3 Sep 2026 — sent directly by Aditya before this tracker existed. Anuj Kumar asked 3 questions before a call; replied 3 Sep 2026 with company/date/value framing, no deck link sent. Awaiting reply.
A6: EPAM Systems | D6: Already contacted directly by Aditya | E6: Unknown | F6: Unknown | G6: N | I6: Sponsor | K6: sameena.mohdali@gmail.com; sameena_ali@epam.com; nandini_bhatnagar@epam.com; nandinib2007@gmail.com; nandinibhatnagar@epam.it | M6: Email | N6: N | O6: Replied | P6: 2026-09-01 | Q6: 2026-09-01 | R6: N | S6: N | T6: N | U6: Backfilled 3 Sep 2026 — sent directly by Aditya before this tracker existed. Nandini Bhatnagar wants to talk after Sept 9; replied 3 Sep 2026 confirming availability. Awaiting her scheduling reply.
A7: Adani Digital Labs | D7: Already contacted directly by Aditya | E7: Unknown | F7: Unknown | G7: N | I7: Sponsor | K7: digitallabs@adani.com; media@adani.com; hrishik.jethi@adani.com; cgarg@adanidigitallabs.com; manishsingh.payal@adani.com; jaladhi.shukla@adani.com; support@adanione.com; cbccyber1@adani.com | M7: Email | N7: N | O7: Sent | P7: 2026-09-02 | Q7: 2026-09-02 | R7: N | S7: N | T7: N | U7: Backfilled 3 Sep 2026 — sent directly by Aditya before this tracker existed. BOUNCE: 4 of 8 BCC addresses bounced (cgarg@adanidigitallabs.com, hrishik.jethi@adani.com, manishsingh.payal@adani.com, digitallabs@adani.com)
A8: Adani AI Labs | D8: Already contacted directly by Aditya | E8: Unknown | F8: Unknown | G8: N | I8: Sponsor | J8: Shalini.singh@adani.com | K8: roy.paul@adani.com; jeet.adani@adani.com; tanushyam.chattopadhyay@adani.com; investor.ael@adani.com | M8: Email | N8: N | O8: Sent | P8: 2026-09-02 | Q8: 2026-09-02 | R8: N | S8: N | T8: N | U8: Backfilled 3 Sep 2026 — sent directly by Aditya before this tracker existed. BOUNCE: 1 of 4 BCC addresses bounced (tanushyam.chattopadhyay@adani.com); also sent separately to Shalini Singh direct
A9: Freshworks | D9: Already contacted directly by Aditya | E9: Unknown | F9: Unknown | G9: N | I9: Sponsor | K9: sales@freshworks.com; pr@freshworks.com; dpo@freshworks.com; ir@freshworks.com | M9: Email | N9: N | O9: Sent | P9: 2026-09-02 | Q9: 2026-09-02 | R9: N | S9: N | T9: N | U9: Backfilled 3 Sep 2026 — sent directly by Aditya before this tracker existed. Automated support-ticket confirmation only — not a personal reply, no action needed yet
A10: Zoho | D10: Already contacted directly by Aditya | E10: Unknown | F10: Unknown | G10: N | I10: Sponsor | K10: sales@zohocorp.com; partner-operations@zohocorp.com; press@zohocorp.com | M10: Email | N10: N | O10: Sent | P10: 2026-09-02 | Q10: 2026-09-02 | R10: N | S10: N | T10: N | U10: Backfilled 3 Sep 2026 — sent directly by Aditya before this tracker existed. Automated partner-ticket confirmation + generic sales-team reply — not personalized, no action needed yet
A11: Myntra | D11: Already contacted directly by Aditya | E11: Unknown | F11: Unknown | G11: N | I11: Sponsor | J11: communications@myntra.com | M11: Email | N11: N | O11: Bounced | P11: 2026-09-02 | Q11: 2026-09-02 | R11: N | S11: N | T11: N | U11: Backfilled 3 Sep 2026 — sent directly by Aditya before this tracker existed. BOUNCE: Address not found (bounced) — only address used, no BCC alternates
A12: Tech Mahindra | D12: Already contacted directly by Aditya | E12: Unknown | F12: Unknown | G12: N | I12: Sponsor | K12: alliances@techmahindra.com; socialmedia@techmahindra.com; mktg@techmahindra.com; media.relations@techmahindra.com | M12: Email | N12: N | O12: Sent | P12: 2026-09-02 | Q12: 2026-09-02 | R12: N | S12: N | T12: N | U12: Backfilled 3 Sep 2026 — sent directly by Aditya before this tracker existed.
A13: BenQ India | D13: Already contacted directly by Aditya | E13: Unknown | F13: Unknown | G13: N | I13: Sponsor | K13: ruchika.singh@benq.com; ankita.karwa@benq.com; rajeev.singh@benq.com (+3 personal-looking gmail addresses also BCC'd) | M13: Email | N13: N | O13: Sent | P13: 2026-09-02 | Q13: 2026-09-02 | R13: N | S13: N | T13: N | U13: Backfilled 3 Sep 2026 — sent directly by Aditya before this tracker existed.
A14: Sennheiser | D14: Already contacted directly by Aditya | E14: Unknown | F14: Unknown | G14: N | I14: Sponsor | K14: sponsoring@sennheiser.com; sarah.talaat@sennheiser.com; felix.teufel@sennheiser.com (+17 more BCC'd, incl. Sonova/Neumann/agency addresses) | M14: Email | N14: N | O14: Sent | P14: 2026-09-02 | Q14: 2026-09-02 | R14: N | S14: N | T14: N | U14: Backfilled 3 Sep 2026 — sent directly by Aditya before this tracker existed.
A15: Runway | B15: Venture-funded AI tool company | C15: San Francisco, US | D15: Gen-4.5 launch + Lionsgate equity partnership for AI-generated franchise content | E15: Y | F15: Y | G15: N | I15: Sponsor | J15: partnerships@runwayml.com | K15: press@runwayml.com | M15: Email | N15: N | O15: Sent | P15: 2026-09-03 | Q15: 2026-09-03 | R15: N | S15: N | T15: N | U15: Sent 3 Sep 2026 — Batch 1 (60), Target Batch 2 research.
A16: Genmo | B16: Venture-funded AI tool company | C16: San Francisco, US | D16: Mochi 1 open text-to-video model, still updated a year on | E16: Y | F16: Y | G16: N | I16: Sponsor | J16: hi@genmo.ai | M16: Email | N16: N | O16: Sent | P16: 2026-09-03 | Q16: 2026-09-03 | R16: N | S16: N | T16: N | U16: Sent 3 Sep 2026 — Batch 1 (60), Target Batch 2 research.
A17: Shengshu Technology (Vidu) | B17: Venture-funded AI tool company | C17: Beijing, China | D17: Alibaba Cloud $290M round backing Vidu world-model ambitions | E17: Y | F17: Y | G17: N | I17: Sponsor | J17: support@vidu.com | M17: Email | N17: N | O17: Sent | P17: 2026-09-03 | Q17: 2026-09-03 | R17: N | S17: N | T17: N | U17: Sent 3 Sep 2026 — Batch 1 (60), Target Batch 2 research.
A18: ElevenLabs | B18: Venture-funded AI tool company | C18: London, UK | D18: New CRO, Canada launch, CLI v1 release | E18: Y | F18: Y | G18: N | I18: Sponsor | J18: press@elevenlabs.io | M18: Email | N18: N | O18: Sent | P18: 2026-09-03 | Q18: 2026-09-03 | R18: N | S18: Y - 2026-09-14 | T18: N | U18: Sent 3 Sep 2026 — Batch 1 (60), Target Batch 2 research. || Day 11 follow-up sent 2026-09-14: new-fact angle (Cannes 2027 flagship now fixed 6-7 Apr 2027 at Palais des Festivals, Road to Cannes selection model, 2026 jury names). Sponsor variant for sponsor track, organizer variant naming edition ownership and retained sponsorship revenue for organizer track.
A19: Murf AI | B19: Venture-funded AI tool company | C19: Bangalore, India | D19: 300+ Forbes 2000 clients, 6M+ users, 20+ languages | E19: Y | F19: Y | G19: N | I19: Sponsor | J19: alliances@murf.ai | K19: enterprise@murf.ai; support@murf.ai | M19: Email | N19: N | O19: Sent | P19: 2026-09-03 | Q19: 2026-09-03 | R19: N | S19: N | T19: N | U19: Sent 3 Sep 2026 — Batch 1 (60), Target Batch 2 research.
A20: NeuralGarage | B20: Venture-funded AI tool company | C20: Mumbai, India | D20: VisualDub — SXSW 2025 winner, lip-sync tech used in Rajinikanth's Coolie | E20: Y | F20: Y | G20: N | I20: Sponsor | J20: info@neuralgarage.com | M20: Email | N20: N | O20: Sent | P20: 2026-09-03 | Q20: 2026-09-03 | R20: N | S20: Y - 2026-09-14 | T20: N | U20: Sent 3 Sep 2026 — Batch 1 (60), Target Batch 2 research. || Day 11 follow-up sent 2026-09-14: new-fact angle (Cannes 2027 flagship now fixed 6-7 Apr 2027 at Palais des Festivals, Road to Cannes selection model, 2026 jury names). Sponsor variant for sponsor track, organizer variant naming edition ownership and retained sponsorship revenue for organizer track.
A21: Synthesia | B21: Venture-funded AI tool company | C21: London, UK | D21: Signed EU Article 50 AI Act code of practice; interactive AI press-officer avatar | E21: Y | F21: Y | G21: N | I21: Sponsor | J21: press@synthesia.io | M21: Email | N21: N | O21: Sent | P21: 2026-09-03 | Q21: 2026-09-03 | R21: N | S21: Y - 2026-09-14 | T21: N | U21: Sent 3 Sep 2026 — Batch 1 (60), Target Batch 2 research. || Day 11 follow-up sent 2026-09-14: new-fact angle (Cannes 2027 flagship now fixed 6-7 Apr 2027 at Palais des Festivals, Road to Cannes selection model, 2026 jury names). Sponsor variant for sponsor track, organizer variant naming edition ownership and retained sponsorship revenue for organizer track.
A22: OpusClip (Opus.pro) | B22: Venture-funded AI tool company | C22: San Francisco, US | D22: SoftBank Vision Fund 2 $20M investment in AI video editing platform | E22: Y | F22: Y | G22: N | I22: Sponsor | J22: contact@opus.pro | M22: Email | N22: N | O22: Sent | P22: 2026-09-03 | Q22: 2026-09-03 | R22: N | S22: Y - 2026-09-14 | T22: N | U22: Sent 3 Sep 2026 — Batch 1 (60), Target Batch 2 research. || Day 11 follow-up sent 2026-09-14: new-fact angle (Cannes 2027 flagship now fixed 6-7 Apr 2027 at Palais des Festivals, Road to Cannes selection model, 2026 jury names). Sponsor variant for sponsor track, organizer variant naming edition ownership and retained sponsorship revenue for organizer track.
A23: Captions (Mirage) | B23: Venture-funded AI tool company | C23: New York, US | D23: $75M raise from General Catalyst Customer Value Fund for Asia expansion | E23: Y | F23: Y | G23: N | I23: Sponsor | J23: press@mirage.app | K23: info@mirage.app | M23: Email | N23: N | O23: Sent | P23: 2026-09-03 | Q23: 2026-09-03 | R23: N | S23: Y - 2026-09-14 | T23: N | U23: Sent 3 Sep 2026 — Batch 1 (60), Target Batch 2 research. || Day 11 follow-up sent 2026-09-14: new-fact angle (Cannes 2027 flagship now fixed 6-7 Apr 2027 at Palais des Festivals, Road to Cannes selection model, 2026 jury names). Sponsor variant for sponsor track, organizer variant naming edition ownership and retained sponsorship revenue for organizer track.
A24: Topaz Labs | B24: Venture-funded AI tool company | C24: Dallas, US | D24: Largest single AI model release in company history; NeuroStream cuts VRAM 95% | E24: Y | F24: Y | G24: N | I24: Sponsor | J24: Press@topazlabs.com | M24: Email | N24: N | O24: Sent | P24: 2026-09-03 | Q24: 2026-09-03 | R24: N | S24: Y - 2026-09-14 | T24: N | U24: Sent 3 Sep 2026 — Batch 1 (60), Target Batch 2 research. || Day 11 follow-up sent 2026-09-14: new-fact angle (Cannes 2027 flagship now fixed 6-7 Apr 2027 at Palais des Festivals, Road to Cannes selection model, 2026 jury names). Sponsor variant for sponsor track, organizer variant naming edition ownership and retained sponsorship revenue for organizer track.
A25: Black Forest Labs | B25: Venture-funded AI tool company | C25: Freiburg, Germany | D25: Martin Scorsese joined as advisor to shape FLUX use in filmmaking pre-production | E25: Y | F25: Y | G25: N | I25: Sponsor | J25: info@blackforestlabs.ai | M25: Email | N25: N | O25: Sent | P25: 2026-09-03 | Q25: 2026-09-03 | R25: N | S25: Y - 2026-09-14 | T25: N | U25: Sent 3 Sep 2026 — Batch 1 (60), Target Batch 2 research. || Day 11 follow-up sent 2026-09-14: new-fact angle (Cannes 2027 flagship now fixed 6-7 Apr 2027 at Palais des Festivals, Road to Cannes selection model, 2026 jury names). Sponsor variant for sponsor track, organizer variant naming edition ownership and retained sponsorship revenue for organizer track.
A26: Stability AI | B26: Venture-funded AI tool company | C26: London, UK | D26: $76M Series B backed by EA/Sony Music/UMG/WMG/AMD Ventures + new WPP partnership | E26: Y | F26: Y | G26: N | I26: Sponsor | J26: partners@stability.ai | K26: press@stability.ai | M26: Email | N26: N | O26: Sent | P26: 2026-09-03 | Q26: 2026-09-03 | R26: N | S26: N | T26: N | U26: Sent 3 Sep 2026 — Batch 1 (60), Target Batch 2 research.
A27: NVIDIA | B27: India-operating hardware & consumer brand | C27: Santa Clara, US (India: Bengaluru/Gurugram) | D27: Cosmos 3 Edge world model + Synthetic Video Detector NIM announced at SIGGRAPH 2026 | E27: Y | F27: Y | G27: N | I27: Sponsor | J27: india-pr@nvidia.com | M27: Email | N27: N | O27: Sent | P27: 2026-09-03 | Q27: 2026-09-03 | R27: N | S27: N | T27: N | U27: Sent 3 Sep 2026 — Batch 1 (60), Target Batch 2 research.
A28: Qualcomm | B28: India-operating hardware & consumer brand | C28: San Diego, US (India offices) | D28: "Snapdragon For India 2026" launch of Snapdragon 6 Gen 5 / 4 Gen 5 | E28: Y | F28: Y | G28: N | I28: Sponsor | J28: corpcomm@qualcomm.com | M28: Email | N28: N | O28: Sent | P28: 2026-09-03 | Q28: 2026-09-03 | R28: N | S28: Y - 2026-09-14 | T28: N | U28: Sent 3 Sep 2026 — Batch 1 (60), Target Batch 2 research. || Day 11 follow-up sent 2026-09-14: new-fact angle (Cannes 2027 flagship now fixed 6-7 Apr 2027 at Palais des Festivals, Road to Cannes selection model, 2026 jury names). Sponsor variant for sponsor track, organizer variant naming edition ownership and retained sponsorship revenue for organizer track.
A29: Sony India | B29: India-operating hardware & consumer brand | C29: Tokyo, Japan (India subsidiary) | D29: ILCE-7V launch with AI-powered Auto Framing and 7K-oversampled 4K/60p video | E29: Y | F29: Y | G29: N | I29: Sponsor | J29: press.india@sony.com | M29: Email | N29: N | O29: Sent | P29: 2026-09-03 | Q29: 2026-09-03 | R29: N | S29: Y - 2026-09-14 | T29: N | U29: Sent 3 Sep 2026 — Batch 1 (60), Target Batch 2 research. || Day 11 follow-up sent 2026-09-14: new-fact angle (Cannes 2027 flagship now fixed 6-7 Apr 2027 at Palais des Festivals, Road to Cannes selection model, 2026 jury names). Sponsor variant for sponsor track, organizer variant naming edition ownership and retained sponsorship revenue for organizer track.
A30: Harman International (JBL) | B30: India-operating hardware & consumer brand | C30: Stamford, US (India office; Samsung-owned) | D30: JBL 80th anniversary; Summit Everest / Summit K2 loudspeaker launch | E30: Y | F30: Y | G30: N | I30: Sponsor | J30: indiaprosales@harman.com | K30: indiaprocare@harman.com; david.glaubke@harman.com | M30: Email | N30: N | O30: Sent | P30: 2026-09-03 | Q30: 2026-09-03 | R30: N | S30: Y - 2026-09-14 | T30: N | U30: Sent 3 Sep 2026 — Batch 1 (60), Target Batch 2 research. || Day 11 follow-up sent 2026-09-14: new-fact angle (Cannes 2027 flagship now fixed 6-7 Apr 2027 at Palais des Festivals, Road to Cannes selection model, 2026 jury names). Sponsor variant for sponsor track, organizer variant naming edition ownership and retained sponsorship revenue for organizer track.
A31: Zebronics | B31: India-operating hardware & consumer brand | C31: Chennai, India | D31: Zeb-PixaPlay 72 Plus — 120-inch, 4000-lumen smart projector | E31: Y | F31: Y | G31: N | I31: Sponsor | J31: enquiry@zebronics.com | M31: Email | N31: N | O31: Sent | P31: 2026-09-03 | Q31: 2026-09-03 | R31: N | S31: Y - 2026-09-14 | T31: N | U31: Sent 3 Sep 2026 — Batch 1 (60), Target Batch 2 research. || Day 11 follow-up sent 2026-09-14: new-fact angle (Cannes 2027 flagship now fixed 6-7 Apr 2027 at Palais des Festivals, Road to Cannes selection model, 2026 jury names). Sponsor variant for sponsor track, organizer variant naming edition ownership and retained sponsorship revenue for organizer track.
A32: Dell Technologies India | B32: India-operating hardware & consumer brand | C32: Round Rock, US (India: Bengaluru/Hyderabad) | D32: Alienware 16X Aurora "Back to School" campaign with Jemimah Rodrigues and Yashraj Mukhate | E32: Y | F32: Y | G32: N | I32: Sponsor | J32: media.relations@dell.com | M32: Email | N32: N | O32: Sent | P32: 2026-09-03 | Q32: 2026-09-03 | R32: N | S32: Y - 2026-09-14 | T32: N | U32: Sent 3 Sep 2026 — Batch 1 (60), Target Batch 2 research. || Day 11 follow-up sent 2026-09-14: new-fact angle (Cannes 2027 flagship now fixed 6-7 Apr 2027 at Palais des Festivals, Road to Cannes selection model, 2026 jury names). Sponsor variant for sponsor track, organizer variant naming edition ownership and retained sponsorship revenue for organizer track.
A33: ASUS India | B33: India-operating hardware & consumer brand | C33: Taipei, Taiwan (India subsidiary) | D33: ROG Flow Z13 Kojima Productions Edition collab (Death Stranding universe) | E33: Y | F33: Y | G33: N | I33: Sponsor | J33: Media@asus.com | M33: Email | N33: N | O33: Sent | P33: 2026-09-03 | Q33: 2026-09-03 | R33: N | S33: Y - 2026-09-14 | T33: N | U33: Sent 3 Sep 2026 — Batch 1 (60), Target Batch 2 research. || Day 11 follow-up sent 2026-09-14: new-fact angle (Cannes 2027 flagship now fixed 6-7 Apr 2027 at Palais des Festivals, Road to Cannes selection model, 2026 jury names). Sponsor variant for sponsor track, organizer variant naming edition ownership and retained sponsorship revenue for organizer track.
A34: Lenovo India | B34: India-operating hardware & consumer brand | C34: Beijing/Morrisville (India subsidiary) | D34: Creator/influencer partnerships program (Grace Gabel, Sabrina Mohan) | E34: Y | F34: Y | G34: N | I34: Sponsor | J34: grace.gabel@lenovo.com | K34: sabrina.mohan@lenovo.com; stephanie.yu@lenovo.com | M34: Email | N34: N | O34: Sent | P34: 2026-09-03 | Q34: 2026-09-03 | R34: N | S34: Y - 2026-09-14 | T34: N | U34: Sent 3 Sep 2026 — Batch 1 (60), Target Batch 2 research. || Day 11 follow-up sent 2026-09-14: new-fact angle (Cannes 2027 flagship now fixed 6-7 Apr 2027 at Palais des Festivals, Road to Cannes selection model, 2026 jury names). Sponsor variant for sponsor track, organizer variant naming edition ownership and retained sponsorship revenue for organizer track.
A35: Western Digital (SanDisk Professional) | B35: India-operating hardware & consumer brand | C35: San Jose, US (India operations) | D35: SanDisk Creator Series launch in India for 4K-6K creators, bundled Adobe CC trial | E35: Y | F35: Y | G35: N | I35: Sponsor | J35: WD.Mediainquiries@wdc.com | M35: Email | N35: N | O35: Sent | P35: 2026-09-03 | Q35: 2026-09-03 | R35: N | S35: Y - 2026-09-14 | T35: N | U35: Sent 3 Sep 2026 — Batch 1 (60), Target Batch 2 research. || Day 11 follow-up sent 2026-09-14: new-fact angle (Cannes 2027 flagship now fixed 6-7 Apr 2027 at Palais des Festivals, Road to Cannes selection model, 2026 jury names). Sponsor variant for sponsor track, organizer variant naming edition ownership and retained sponsorship revenue for organizer track.
A36: Samsung India | B36: India-operating hardware & consumer brand | C36: Suwon, South Korea (India subsidiary) | D36: Brut India partnership covering 2026 Cannes red carpet via Galaxy S26 Ultra creator storytelling | E36: Y | F36: Y | G36: N | I36: Sponsor | J36: corpcommindia@samsung.com | M36: Email | N36: N | O36: Sent | P36: 2026-09-03 | Q36: 2026-09-03 | R36: N | S36: Y - 2026-09-14 | T36: N | U36: Sent 3 Sep 2026 — Batch 1 (60), Target Batch 2 research. || Day 11 follow-up sent 2026-09-14: new-fact angle (Cannes 2027 flagship now fixed 6-7 Apr 2027 at Palais des Festivals, Road to Cannes selection model, 2026 jury names). Sponsor variant for sponsor track, organizer variant naming edition ownership and retained sponsorship revenue for organizer track.
A37: Krutrim AI (Ola Krutrim) | B37: Indian AI infrastructure | C37: Bengaluru, India | D37: First annual net profit; revenue nearly tripled; 25+ enterprise clients | E37: Y | F37: Y | G37: N | I37: Sponsor | J37: sales@olakrutrim.com | K37: cloudsupport@olakrutrim.com | M37: Email | N37: N | O37: Sent | P37: 2026-09-03 | Q37: 2026-09-03 | R37: N | S37: Y - 2026-09-14 | T37: N | U37: Sent 3 Sep 2026 — Batch 1 (60), Target Batch 2 research. || Day 11 follow-up sent 2026-09-14: new-fact angle (Cannes 2027 flagship now fixed 6-7 Apr 2027 at Palais des Festivals, Road to Cannes selection model, 2026 jury names). Sponsor variant for sponsor track, organizer variant naming edition ownership and retained sponsorship revenue for organizer track.
A38: Yotta Data Services | B38: Indian AI infrastructure | C38: Navi Mumbai, India | D38: Frost & Sullivan 2026 Indian Company of the Year for Sovereign AI Infrastructure | E38: Y | F38: Y | G38: N | I38: Sponsor | J38: marketing@yotta.com | K38: info@yotta.com | M38: Email | N38: N | O38: Sent | P38: 2026-09-03 | Q38: 2026-09-03 | R38: N | S38: N | T38: N | U38: Sent 3 Sep 2026 — Batch 1 (60), Target Batch 2 research.
A39: E2E Networks | B39: Indian AI infrastructure | C39: New Delhi, India | D39: ₹1,000 crore Blackwell GPU order + new NVIDIA B200 cluster on TIR platform | E39: Y | F39: Y | G39: N | I39: Sponsor | J39: sales@e2enetworks.com | M39: Email | N39: N | O39: Sent | P39: 2026-09-03 | Q39: 2026-09-03 | R39: N | S39: Y - 2026-09-14 | T39: N | U39: Sent 3 Sep 2026 — Batch 1 (60), Target Batch 2 research. || Day 11 follow-up sent 2026-09-14: new-fact angle (Cannes 2027 flagship now fixed 6-7 Apr 2027 at Palais des Festivals, Road to Cannes selection model, 2026 jury names). Sponsor variant for sponsor track, organizer variant naming edition ownership and retained sponsorship revenue for organizer track.
A40: Netweb Technologies | B40: Indian AI infrastructure | C40: Faridabad, India | D40: Launched Tyrone ParallelStor Velox unified data platform for AI/HPC | E40: Y | F40: Y | G40: N | I40: Sponsor | J40: mktkol@netwebindia.com | K40: info@netwebindia.com; hydsales@netwebindia.com | M40: Email | N40: N | O40: Sent | P40: 2026-09-03 | Q40: 2026-09-03 | R40: N | S40: Y - 2026-09-14 | T40: N | U40: Sent 3 Sep 2026 — Batch 1 (60), Target Batch 2 research. || Day 11 follow-up sent 2026-09-14: new-fact angle (Cannes 2027 flagship now fixed 6-7 Apr 2027 at Palais des Festivals, Road to Cannes selection model, 2026 jury names). Sponsor variant for sponsor track, organizer variant naming edition ownership and retained sponsorship revenue for organizer track.
...

Sheet LinkedIn Tracker
A1: WAIFF India — LinkedIn Tracker (80 profiles/week, one dated batch at a time)
A2: Source only from companies already in the email batch — no separate LinkedIn universe. No repeats, ever. Row 4 is an example only.
A3: Batch # | B3: Batch date | C3: Name | D3: Title | E3: Company | F3: Profile URL | G3: Sourced from an email-batch company? (Y/N) | H3: Connection sent date | I3: Connection status | J3: Message sent date | K3: Reply? (Y/N) | L3: Reply date | M3: Follow-up date | N3: Notes
A4: 1 | B4: 2026-09-03 | C4: Jane Doe | D4: Head of Partnerships | E4: Runway AI, Inc. | F4: https://www.linkedin.com/in/example-profile | G4: Y | I4: Pending | K4: N | N4: EXAMPLE ROW — edit or delete, do not count as real data
A5: 1 | B5: 2026-09-03 | C5: Michelle Kwon | D5: Head of Operations and Partnerships | E5: Runway | F5: https://www.linkedin.com/in/michelleskwon/ | G5: Y | I5: Pending | K5: N | N5: Connection note: Hi Michelle, following Runway's Gen-4.5 and the Lionsgate deal closely. I'm building the founding sponsor group for WAiFF's India edition, launching December 2026. Would love to connect.
A6: 1 | B6: 2026-09-03 | C6: Tony Pu | D6: Community & Partnerships | E6: Kuaishou / Kling AI | F6: https://www.linkedin.com/in/tpu0817/ | G6: Y | I6: Pending | K6: N | N6: Connection note: Hi Tony, Kling AI's growth this year has been remarkable. I'm the India Ambassador for WAiFF, the AI film festival held at Cannes, building our India sponsor group. Would love to connect.
A7: 1 | B7: 2026-09-03 | C7: Paras Jain | D7: Genmo (title unconfirmed) | E7: Genmo | F7: https://www.linkedin.com/in/jain-paras/ | G7: Y | I7: Pending | K7: N | N7: Connection note: Hi Paras, Mochi 1's open approach to text-to-video stood out to me. I'm building the founding sponsor group for WAiFF India, launching December 2026. Would love to connect.
A8: 1 | B8: 2026-09-03 | C8: Franz-Josef Schrepf | D8: Revenue & Partnerships | E8: OpusClip | F8: https://www.linkedin.com/in/franz-josef-schrepf/ | G8: Y | I8: Pending | K8: N | N8: Connection note: Hi Franz-Josef, congrats on the SoftBank Vision Fund 2 investment. I'm the India Ambassador for WAiFF, the AI film festival at Cannes, building our India sponsor group. Would love to connect.
A9: 1 | B9: 2026-09-03 | C9: Callie Costello | D9: Product & Brand Marketing | E9: Mirage (Captions) | F9: https://www.linkedin.com/in/calliegcostello/ | G9: Y | I9: Pending | K9: N | N9: Connection note: Hi Callie, congrats on the $75M raise and the Asia expansion. I'm building the founding sponsor group for WAiFF's India edition, launching December 2026. Would love to connect.
A10: 1 | B10: 2026-09-03 | C10: Ross Shain | D10: Principal Creative Technologist | E10: Topaz Labs | F10: https://www.linkedin.com/in/rshain/ | G10: Y | I10: Pending | K10: N | N10: Connection note: Hi Ross, the Next-Gen model launch and NeuroStream tech are impressive. I'm the India Ambassador for WAiFF, the AI film festival at Cannes, building our India sponsor group. Would love to connect.
A11: 1 | B11: 2026-09-03 | C11: Michelle Belcic | D11: VP Sales & Partnerships | E11: Photoroom | F11: https://fr.linkedin.com/in/michellebelcic | G11: Y | I11: Pending | K11: N | N11: Connection note: Hi Michelle, Photoroom's H1 2026 product recap was impressive. I'm building the founding sponsor group for WAiFF's India edition, launching December 2026. Would love to connect.
A12: 1 | B12: 2026-09-03 | C12: Anthony Ganjou | D12: Co-Founder | E12: Move AI | F12: https://www.linkedin.com/in/anthonyganjou/ | G12: Y | I12: Pending | K12: N | N12: Connection note: Hi Anthony, Move AI's marker-less mocap work with studios like Disney and Paramount is exactly the kind of tool WAiFF's filmmakers need. Building our India sponsor group. Would love to connect.
A13: 1 | B13: 2026-09-03 | C13: Sofía Goble | D13: Operations (unconfirmed current role) | E13: Cuebric | F13: https://www.linkedin.com/in/sof%C3%ADa-goble-17a56a1a3/ | G13: Y | I13: Pending | K13: N | N13: Connection note: Hi Sofía, Cuebric's virtual-production work with Disguise caught my eye. I'm building the founding sponsor group for WAiFF's India edition, launching December 2026. Would love to connect.
A14: 1 | B14: 2026-09-03 | C14: Parthajit Sar | D14: Marketing programs | E14: NVIDIA | F14: https://in.linkedin.com/in/parthajit-sar | G14: Y | I14: Pending | K14: N | N14: Connection note: Hi Parthajit, NVIDIA's Cosmos 3 Edge announcement at SIGGRAPH was a big one for AI filmmaking. I'm building WAiFF's India sponsor group, launching December 2026. Would love to connect.
A15: 1 | B15: 2026-09-03 | C15: Vishal Dhupar | D15: Managing Director, Asia South | E15: NVIDIA | F15: https://in.linkedin.com/in/vishaldhupar | G15: Y | I15: Pending | K15: N | N15: Connection note: Hi Vishal, I'm the India Ambassador for WAiFF, the AI film festival held at Cannes, building our founding India sponsor group launching December 2026. Would love to connect.
... A135: 4 | B135: 2026-09-03 | C135: Colan Sewell | D135: VP, Chief Revenue Officer, Reality Labs | E135: Meta | F135: https://www.linkedin.com/in/colansewell/ | G135: Y | I135: Pending | K135: N | N135: Most senior revenue/partnerships executive in Reality Labs.

Sheet Gmail Tracker
A1: WAIFF India — Gmail Tracker (one send per company)
A2: One body per company: best address in To:, other addresses at that same company in BCC. Never BCC across different companies. Row 4 is an example only.
A3: Date sent | B3: Company | C3: Channel | D3: To address | E3: BCC addresses | F3: Subject line | G3: Bounced? (Y/N) | H3: Reply received? (Y/N) | I3: Reply date | J3: Follow-up Day 4 sent (Y/N) | K3: Follow-up Day 11 sent (Y/N) | L3: Follow-up Day 25 sent (Y/N) | M3: Meeting booked? (Y/N) | N3: Meeting date | O3: Status | P3: Notes
A4: 2026-09-01 | B4: Radisson Blu | C4: Email | D4: communication@radissonhotels.com | F4: Partnership Opportunity with WAIFF India — Radisson Blu x World AI Film Festival | G4: N | H4: Y | I4: 2026-09-02 | J4: N | K4: N | L4: N | M4: N | O4: Replied | P4: Sent before this tracker existed — backfilled from Gmail search 3 Sep 2026. Anuj Kumar (Marketing Manager, South Asia) asked 3 specific questions before a call. Replied 3 Sep 2026: covered India edition (Dec 2026, Mumbai), JW Marriott Cannes as existing global sponsor, what Radisson gets (network-wide visibility, access, association) and what WAiFF needs (VIP accommodation/hosting, brand partner role, not just venue). No Canva/deck link sent per standing rule. Asked for a call after 2 PM IST. Awaiting reply.
A5: 2026-09-01 | B5: EPAM Systems | C5: Email | D5: (BCC only — see BCC column) | E5: sameena.mohdali@gmail.com; sameena_ali@epam.com; nandini_bhatnagar@epam.com; nandinib2007@gmail.com; nandinibhatnagar@epam.it | F5: Partnership Opportunity with WAIFF India — EPAM Systems x World AI Film Festival | G5: N | H5: Y | I5: 2026-09-02 | J5: N | K5: N | L5: N | M5: N | O5: Replied | P5: Sent before this tracker existed — backfilled from Gmail search 3 Sep 2026. Nandini Bhatnagar (Sr Director Marketing) wants to talk after Sept 9. Replied 3 Sep 2026 confirming availability anytime after 12:00 PM IST, around 4:00 PM IST or later. Awaiting her scheduling reply.
A6: 2026-09-02 | B6: Adani Digital Labs | C6: Email | D6: (BCC only — see BCC column) | E6: digitallabs@adani.com; media@adani.com; hrishik.jethi@adani.com; cgarg@adanidigitallabs.com; manishsingh.payal@adani.com; jaladhi.shukla@adani.com; support@adanione.com; cbccyber1@adani.com | F6: Partnership Opportunity with WAIFF India — Adani Digital Labs x World AI Film Festival | G6: Y | H6: N | J6: N | K6: N | L6: N | M6: N | O6: Bounced | P6: Sent before this tracker existed — backfilled from Gmail search 3 Sep 2026. BOUNCE: 4 of 8 BCC addresses bounced (cgarg@adanidigitallabs.com, hrishik.jethi@adani.com, manishsingh.payal@adani.com, digitallabs@adani.com)
A7: 2026-09-02 | B7: Adani AI Labs | C7: Email | D7: Shalini.singh@adani.com | E7: roy.paul@adani.com; jeet.adani@adani.com; tanushyam.chattopadhyay@adani.com; investor.ael@adani.com | F7: Partnership Opportunity with WAIFF India — Adani AI Labs x World AI Film Festival | G7: Y | H7: N | J7: N | K7: N | L7: N | M7: N | O7: Bounced | P7: Sent before this tracker existed — backfilled from Gmail search 3 Sep 2026. BOUNCE: 1 of 4 BCC addresses bounced (tanushyam.chattopadhyay@adani.com); also sent separately to Shalini Singh direct
A8: 2026-09-02 | B8: Freshworks | C8: Email | D8: (BCC only — see BCC column) | E8: sales@freshworks.com; pr@freshworks.com; dpo@freshworks.com; ir@freshworks.com | F8: Partnership Opportunity with WAIFF India — Freshworks x World AI Film Festival | G8: N | H8: Y | I8: 2026-09-02 | J8: N | K8: N | L8: N | M8: N | O8: Sent | P8: Sent before this tracker existed — backfilled from Gmail search 3 Sep 2026. Automated support-ticket confirmation only — not a personal reply, no action needed yet
A9: 2026-09-02 | B9: Zoho | C9: Email | D9: (BCC only — see BCC column) | E9: sales@zohocorp.com; partner-operations@zohocorp.com; press@zohocorp.com | F9: Partnership Opportunity with WAIFF India — Zoho x World AI Film Festival | G9: N | H9: Y | I9: 2026-09-02 | J9: N | K9: N | L9: N | M9: N | O9: Sent | P9: Sent before this tracker existed — backfilled from Gmail search 3 Sep 2026. Automated partner-ticket confirmation + generic sales-team reply — not personalized, no action needed yet
A10: 2026-09-02 | B10: Myntra | C10: Email | D10: communications@myntra.com | F10: Partnership Opportunity with WAIFF India — Myntra x World AI Film Festival | G10: Y | H10: N | J10: N | K10: N | L10: N | M10: N | O10: Bounced | P10: Sent before this tracker existed — backfilled from Gmail search 3 Sep 2026. BOUNCE: Address not found (bounced) — only address used, no BCC alternates
A11: 2026-09-02 | B11: Tech Mahindra | C11: Email | D11: (BCC only — see BCC column) | E11: alliances@techmahindra.com; socialmedia@techmahindra.com; mktg@techmahindra.com; media.relations@techmahindra.com | F11: Partnership Opportunity with WAIFF India — Tech Mahindra x World AI Film Festival | G11: N | H11: N | J11: N | K11: Y | L11: N | M11: N | O11: Sent | P11: Sent before this tracker existed — backfilled from Gmail search 3 Sep 2026.
A12: 2026-09-02 | B12: BenQ India | C12: Email | D12: (BCC only — see BCC column) | E12: ruchika.singh@benq.com; ankita.karwa@benq.com; rajeev.singh@benq.com (+3 personal-looking gmail addresses also BCC'd) | F12: Partnership Opportunity with WAIFF India — BenQ India x World AI Film Festival | G12: N | H12: N | J12: N | K12: Y | L12: N | M12: N | O12: Sent | P12: Sent before this tracker existed — backfilled from Gmail search 3 Sep 2026.
A13: 2026-09-02 | B13: Sennheiser | C13: Email | D13: (BCC only — see BCC column) | E13: sponsoring@sennheiser.com; sarah.talaat@sennheiser.com; felix.teufel@sennheiser.com (+17 more BCC'd, incl. Sonova/Neumann/agency addresses) | F13: Partnership Opportunity with WAIFF India — Sennheiser x World AI Film Festival | G13: N | H13: N | J13: N | K13: Y | L13: N | M13: N | O13: Sent | P13: Sent before this tracker existed — backfilled from Gmail search 3 Sep 2026.
A14: 2026-09-03 | B14: Runway AI, Inc. | C14: Email | D14: partnerships@runwayml.com | E14: press@runwayml.com | F14: Partnering with WAiFF India — Runway x World AI Film Festival | G14: N | H14: N | J14: Y - 2026-09-07 | K14: Y - 2026-09-14 | L14: N | M14: N | O14: Sent | P14: Real send, confirmed via Gmail — landed clean, no bounce, no reply yet. | DAY-4 FOLLOW-UP SENT 7 Sep. Carried genuinely new information: the verified sponsor roster (CapCut/ByteDance, MiniMax, JW Marriott Cannes, LOTTE, Morphic, Skolae) and the official tier benefits, both extracted from the WAiFF deck on 7 Sep. Several were also reframed from sponsor pitch to organizer/jury/masterclass conversation where that fit the company better. || Day 11 follow-up sent 2026-09-14: new-fact angle (Cannes 2027 flagship now fixed 6-7 Apr 2027 at Palais des Festivals, Road to Cannes selection model, 2026 jury names). Sponsor variant for sponsor track, organizer variant naming edition ownership and retained sponsorship revenue for organizer track.
A15: 2026-09-03 | B15: Runway | C15: Email | D15: partnerships@runwayml.com | E15: press@runwayml.com | F15: WAIFF India x Runway — AI Cinema Partnership | G15: N | H15: N | J15: Y - 2026-09-07 | K15: Y - 2026-09-22 (skipped, see note) | L15: N | M15: N | O15: Sent | P15: Sent 3 Sep 2026 — Batch 1 (60), Target Batch 2 research. | DAY-4 FOLLOW-UP SENT 7 Sep. Carried genuinely new information: the verified sponsor roster (CapCut/ByteDance, MiniMax, JW Marriott Cannes, LOTTE, Morphic, Skolae) and the official tier benefits, both extracted from the WAiFF deck on 7 Sep. Several were also reframed from sponsor pitch to organizer/jury/masterclass conversation where that fit the company better. || 2026-09-22: Runway got an unplanned 3rd touch on 9/14 (new Cannes 2027 dates) only 8 days ago - skipped today's Day11 to avoid a 4th message this close. Next touch not before ~9/28.
A16: 2026-09-03 | B16: Genmo | C16: Email | D16: hi@genmo.ai | F16: WAIFF India x Genmo — AI Cinema Partnership | G16: N | H16: N | J16: Y - 2026-09-07 | K16: Y - 2026-09-22 (skipped, see note) | L16: N | M16: N | O16: Sent | P16: Sent 3 Sep 2026 — Batch 1 (60), Target Batch 2 research. | DAY-4 FOLLOW-UP SENT 7 Sep. Carried genuinely new information: the verified sponsor roster (CapCut/ByteDance, MiniMax, JW Marriott Cannes, LOTTE, Morphic, Skolae) and the official tier benefits, both extracted from the WAiFF deck on 7 Sep. Several were also reframed from sponsor pitch to organizer/jury/masterclass conversation where that fit the company better. || 2026-09-22: Genmo got a DUPLICATE fresh cold email on 9/13 (new thread, not a real follow-up) on top of the proper 9/7 Day4 follow-up - skipped today's Day11, already touched 9 days ago. Flag: duplicate-contact bug from a past batch, not a real Day11.
A17: 2026-09-03 | B17: Shengshu Technology (Vidu) | C17: Email | D17: support@vidu.com | F17: WAIFF India x Shengshu Technology (Vidu) — AI Cinema Partnership | G17: N | H17: Y | I17: 2026-09-08 | J17: Y - 2026-09-07 | K17: Y - 2026-09-19 (live conversation, covered via direct reply not generic followup) | L17: N | M17: N | O17: Replied - engaged conversation | P17: Sent 3 Sep 2026 — Batch 1 (60), Target Batch 2 research. | DAY-4 FOLLOW-UP SENT 7 Sep. Carried genuinely new information: the verified sponsor roster (CapCut/ByteDance, MiniMax, JW Marriott Cannes, LOTTE, Morphic, Skolae) and the official tier benefits, both extracted from the WAiFF deck on 7 Sep. Several were also reframed from sponsor pitch to organizer/jury/masterclass conversation where that fit the company better. || CORRECTION 2026-09-22: this IS actively engaged. Han (Runjie Han, Head of Operations, shengshu.ai) replied 9/8 asking to learn more, Aditya answered same day, sent detailed opportunity outline 9/10, and sent a further concrete follow-up 9/19 (3 days ago). This is a live conversation, not a cold lead. Do NOT send a generic Day11 follow-up here. Separately a duplicate cold email went to support@vidu.com again on 9/13 under a different subject line, unrelated to the live Han thread — flagged as a duplicate-contact cleanup item, no action needed now.
A18: 2026-09-03 | B18: ElevenLabs | C18: Email | D18: press@elevenlabs.io | F18: WAIFF India x ElevenLabs — AI Cinema Partnership | G18: N | H18: N | J18: Y - 2026-09-07 | K18: Y | L18: N | M18: N | O18: Sent | P18: Sent 3 Sep 2026 — Batch 1 (60), Target Batch 2 research. | DAY-4 FOLLOW-UP SENT 7 Sep. Carried genuinely new information: the verified sponsor roster (CapCut/ByteDance, MiniMax, JW Marriott Cannes, LOTTE, Morphic, Skolae) and the official tier benefits, both extracted from the WAiFF deck on 7 Sep. Several were also reframed from sponsor pitch to organizer/jury/masterclass conversation where that fit the company better. || Day 11 follow-up sent 2026-09-14: new-fact angle (Cannes 2027 flagship now fixed 6-7 Apr 2027 at Palais des Festivals, Road to Cannes selection model, 2026 jury names). Sponsor variant for sponsor track, organizer variant naming edition ownership and retained sponsorship revenue for organizer track. | Day-11 follow-up sent 2026-09-23, msgid 1a0cdce1a73bd6c5. Updated with Cannes 6-7 Apr 2027 + 2027 jury (Agnès Jaoui President).
A19: 2026-09-03 | B19: Murf AI | C19: Email | D19: alliances@murf.ai | E19: enterprise@murf.ai; support@murf.ai | F19: WAIFF India x Murf AI — AI Cinema Partnership | G19: N | H19: N | J19: Y - 2026-09-07 | K19: Y - 2026-09-22 (skipped, see note) | L19: N | M19: N | O19: Sent | P19: Sent 3 Sep 2026 — Batch 1 (60), Target Batch 2 research. | DAY-4 FOLLOW-UP SENT 7 Sep. Carried genuinely new information: the verified sponsor roster (CapCut/ByteDance, MiniMax, JW Marriott Cannes, LOTTE, Morphic, Skolae) and the official tier benefits, both extracted from the WAiFF deck on 7 Sep. Several were also reframed from sponsor pitch to organizer/jury/masterclass conversation where that fit the company better. || 2026-09-22: Murf AI got a DUPLICATE fresh cold email on 9/13 (new thread) on top of the proper 9/7 Day4 follow-up - skipped today's Day11, already touched 9 days ago. Same duplicate-contact bug as Genmo/Stability.
A20: 2026-09-03 | B20: NeuralGarage | C20: Email | D20: info@neuralgarage.com | F20: WAIFF India x NeuralGarage — AI Cinema Partnership | G20: N | H20: N | J20: Y - 2026-09-07 | K20: Y | L20: N | M20: N | O20: Sent | P20: Sent 3 Sep 2026 — Batch 1 (60), Target Batch 2 research. | DAY-4 FOLLOW-UP SENT 7 Sep. Carried genuinely new information: the verified sponsor roster (CapCut/ByteDance, MiniMax, JW Marriott Cannes, LOTTE, Morphic, Skolae) and the official tier benefits, both extracted from the WAiFF deck on 7 Sep. Several were also reframed from sponsor pitch to organizer/jury/masterclass conversation where that fit the company better. || Day 11 follow-up sent 2026-09-14: new-fact angle (Cannes 2027 flagship now fixed 6-7 Apr 2027 at Palais des Festivals, Road to Cannes selection model, 2026 jury names). Sponsor variant for sponsor track, organizer variant naming edition ownership and retained sponsorship revenue for organizer track. | Day-11 follow-up sent 2026-09-23, msgid 1a0cdce2582fee41. Updated with Cannes 6-7 Apr 2027 + 2027 jury (Agnès Jaoui President).
A21: 2026-09-03 | B21: Synthesia | C21: Email | D21: press@synthesia.io | F21: WAIFF India x Synthesia — AI Cinema Partnership | G21: N | H21: N | J21: Y - 2026-09-07 | K21: Y | L21: N | M21: N | O21: Sent | P21: Sent 3 Sep 2026 — Batch 1 (60), Target Batch 2 research. | DAY-4 FOLLOW-UP SENT 7 Sep. Carried genuinely new information: the verified sponsor roster (CapCut/ByteDance, MiniMax, JW Marriott Cannes, LOTTE, Morphic, Skolae) and the official tier benefits, both extracted from the WAiFF deck on 7 Sep. Several were also reframed from sponsor pitch to organizer/jury/masterclass conversation where that fit the company better. || Day 11 follow-up sent 2026-09-14: new-fact angle (Cannes 2027 flagship now fixed 6-7 Apr 2027 at Palais des Festivals, Road to Cannes selection model, 2026 jury names). Sponsor variant for sponsor track, organizer variant naming edition ownership and retained sponsorship revenue for organizer track. | Day-11 follow-up sent 2026-09-23, msgid 1a0cdce2b2574fe5. Updated with Cannes 6-7 Apr 2027 + 2027 jury (Agnès Jaoui President).
A22: 2026-09-03 | B22: OpusClip (Opus.pro) | C22: Email | D22: contact@opus.pro | F22: WAIFF India x OpusClip (Opus.pro) — AI Cinema Partnership | G22: N | H22: N | J22: Y - 2026-09-07 | K22: Y | L22: N | M22: N | O22: Sent | P22: Sent 3 Sep 2026 — Batch 1 (60), Target Batch 2 research. | DAY-4 FOLLOW-UP SENT 7 Sep. Carried genuinely new information: the verified sponsor roster (CapCut/ByteDance, MiniMax, JW Marriott Cannes, LOTTE, Morphic, Skolae) and the official tier benefits, both extracted from the WAiFF deck on 7 Sep. Several were also reframed from sponsor pitch to organizer/jury/masterclass conversation where that fit the company better. || Day 11 follow-up sent 2026-09-14: new-fact angle (Cannes 2027 flagship now fixed 6-7 Apr 2027 at Palais des Festivals, Road to Cannes selection model, 2026 jury names). Sponsor variant for sponsor track, organizer variant naming edition ownership and retained sponsorship revenue for organizer track. | Day-11 follow-up sent 2026-09-23, msgid 1a0cdce31e8a75ce. Updated with Cannes 6-7 Apr 2027 + 2027 jury (Agnès Jaoui President).
A23: 2026-09-03 | B23: Captions (Mirage) | C23: Email | D23: press@mirage.app | E23: info@mirage.app | F23: WAIFF India x Captions (Mirage) — AI Cinema Partnership | G23: N | H23: N | J23: Y - 2026-09-07 | K23: Y | L23: N | M23: N | O23: Sent | P23: Sent 3 Sep 2026 — Batch 1 (60), Target Batch 2 research. | DAY-4 FOLLOW-UP SENT 7 Sep. Carried genuinely new information: the verified sponsor roster (CapCut/ByteDance, MiniMax, JW Marriott Cannes, LOTTE, Morphic, Skolae) and the official tier benefits, both extracted from the WAiFF deck on 7 Sep. Several were also reframed from sponsor pitch to organizer/jury/masterclass conversation where that fit the company better. || Day 11 follow-up sent 2026-09-14: new-fact angle (Cannes 2027 flagship now fixed 6-7 Apr 2027 at Palais des Festivals, Road to Cannes selection model, 2026 jury names). Sponsor variant for sponsor track, organizer variant naming edition ownership and retained sponsorship revenue for organizer track. | Day-11 follow-up sent 2026-09-23, msgid 1a0cdce38cb88fae. Updated with Cannes 6-7 Apr 2027 + 2027 jury (Agnès Jaoui President).
A24: 2026-09-03 | B24: Topaz Labs | C24: Email | D24: Press@topazlabs.com | F24: WAIFF India x Topaz Labs — AI Cinema Partnership | G24: N | H24: N | J24: Y - 2026-09-07 | K24: Y | L24: N | M24: N | O24: Sent | P24: Sent 3 Sep 2026 — Batch 1 (60), Target Batch 2 research. | DAY-4 FOLLOW-UP SENT 7 Sep. Carried genuinely new information: the verified sponsor roster (CapCut/ByteDance, MiniMax, JW Marriott Cannes, LOTTE, Morphic, Skolae) and the official tier benefits, both extracted from the WAiFF deck on 7 Sep. Several were also reframed from sponsor pitch to organizer/jury/masterclass conversation where that fit the company better. || Day 11 follow-up sent 2026-09-14: new-fact angle (Cannes 2027 flagship now fixed 6-7 Apr 2027 at Palais des Festivals, Road to Cannes selection model, 2026 jury names). Sponsor variant for sponsor track, organizer variant naming edition ownership and retained sponsorship revenue for organizer track. | Day-11 follow-up sent 2026-09-23, msgid 1a0cdce41c4aeb4a. Updated with Cannes 6-7 Apr 2027 + 2027 jury (Agnès Jaoui President).
A25: 2026-09-03 | B25: Black Forest Labs | C25: Email | D25: info@blackforestlabs.ai | F25: WAIFF India x Black Forest Labs — AI Cinema Partnership | G25: N | H25: N | J25: Y - 2026-09-07 | K25: Y | L25: N | M25: N | O25: Sent | P25: Sent 3 Sep 2026 — Batch 1 (60), Target Batch 2 research. | DAY-4 FOLLOW-UP SENT 7 Sep. Carried genuinely new information: the verified sponsor roster (CapCut/ByteDance, MiniMax, JW Marriott Cannes, LOTTE, Morphic, Skolae) and the official tier benefits, both extracted from the WAiFF deck on 7 Sep. Several were also reframed from sponsor pitch to organizer/jury/masterclass conversation where that fit the company better. || Day 11 follow-up sent 2026-09-14: new-fact angle (Cannes 2027 flagship now fixed 6-7 Apr 2027 at Palais des Festivals, Road to Cannes selection model, 2026 jury names). Sponsor variant for sponsor track, organizer variant naming edition ownership and retained sponsorship revenue for organizer track. | Day-11 follow-up sent 2026-09-23, msgid 1a0cdce483f4a18d. Updated with Cannes 6-7 Apr 2027 + 2027 jury (Agnès Jaoui President).
A26: 2026-09-03 | B26: Stability AI | C26: Email | D26: partners@stability.ai | E26: press@stability.ai | F26: WAIFF India x Stability AI — AI Cinema Partnership | G26: N | H26: N | J26: Y - 2026-09-07 | K26: Y - 2026-09-22 (skipped, see note) | L26: N | M26: N | O26: Sent | P26: Sent 3 Sep 2026 — Batch 1 (60), Target Batch 2 research. | DAY-4 FOLLOW-UP SENT 7 Sep. Carried genuinely new information: the verified sponsor roster (CapCut/ByteDance, MiniMax, JW Marriott Cannes, LOTTE, Morphic, Skolae) and the official tier benefits, both extracted from the WAiFF deck on 7 Sep. Several were also reframed from sponsor pitch to organizer/jury/masterclass conversation where that fit the company better. || 2026-09-22: Stability AI got a DUPLICATE fresh cold email on 9/13 (new thread) on top of the proper 9/7 Day4 follow-up - skipped today's Day11, already touched 9 days ago. Same duplicate-contact bug as Genmo/Murf.
A27: 2026-09-03 | B27: NVIDIA | C27: Email | D27: india-pr@nvidia.com | F27: WAIFF India x NVIDIA — AI Cinema Partnership | G27: N | H27: N | J27: Y - 2026-09-19 | K27: Y | L27: N | M27: N | O27: Sent | P27: Sent 3 Sep 2026 — Batch 1 (60), Target Batch 2 research. || 2026-09-19: check-in sent to Kavita Aroor (karoor@nvidia.com, cc Shristi Mahnot) on the live thread after her 2-week review window, MsgID 1a0b9366e4eee7f9. Note: Aditya also sent a separate cold email to 7 NVIDIA employees (BCC) on 2026-09-17. || CORRECTION 2026-09-22: the india-pr@nvidia.com address (this row) never replied directly. The real live NVIDIA relationship is with Kavita Aroor (karoor@nvidia.com) on a separate thread — she replied 9/3 ("will review internally, revert in a couple weeks"), Aditya sent a check-in 9/19 (3 days ago), still awaiting her response. Do NOT send another follow-up to NVIDIA today, the 9/19 check-in already covers it. Also found: a 7-person BCC blast to NVIDIA on 9/3 (separate from this row) got only a boilerplate Inception-program redirect, no real reply. NVIDIA has 3-4 disconnected threads under one company name — needs manual consolidation, flagged to Aditya. | Day-11 follow-up sent 2026-09-23, msgid 1a0cdce4e1d1f8a5. Updated with Cannes 6-7 Apr 2027 + 2027 jury (Agnès Jaoui President).
A28: 2026-09-03 | B28: Qualcomm | C28: Email | D28: corpcomm@qualcomm.com | F28: WAIFF India x Qualcomm — AI Cinema Partnership | G28: N | H28: N | J28: Y - 2026-09-07 | K28: Y | L28: N | M28: N | O28: Sent | P28: Sent 3 Sep 2026 — Batch 1 (60), Target Batch 2 research. | DAY-4 FOLLOW-UP SENT 7 Sep. Carried genuinely new information: the verified sponsor roster (CapCut/ByteDance, MiniMax, JW Marriott Cannes, LOTTE, Morphic, Skolae) and the official tier benefits, both extracted from the WAiFF deck on 7 Sep. Several were also reframed from sponsor pitch to organizer/jury/masterclass conversation where that fit the company better. || Day 11 follow-up sent 2026-09-14: new-fact angle (Cannes 2027 flagship now fixed 6-7 Apr 2027 at Palais des Festivals, Road to Cannes selection model, 2026 jury names). Sponsor variant for sponsor track, organizer variant naming edition ownership and retained sponsorship revenue for organizer track. | Day-11 follow-up sent 2026-09-23, msgid 1a0cdce57d742093. Updated with Cannes 6-7 Apr 2027 + 2027 jury (Agnès Jaoui President).
A29: 2026-09-03 | B29: Sony India | C29: Email | D29: press.india@sony.com | F29: WAIFF India x Sony India — AI Cinema Partnership | G29: N | H29: N | J29: Y - 2026-09-07 | K29: Y | L29: N | M29: N | O29: Sent | P29: Sent 3 Sep 2026 — Batch 1 (60), Target Batch 2 research. | DAY-4 FOLLOW-UP SENT 7 Sep. Carried genuinely new information: the verified sponsor roster (CapCut/ByteDance, MiniMax, JW Marriott Cannes, LOTTE, Morphic, Skolae) and the official tier benefits, both extracted from the WAiFF deck on 7 Sep. Several were also reframed from sponsor pitch to organizer/jury/masterclass conversation where that fit the company better. || Day 11 follow-up sent 2026-09-14: new-fact angle (Cannes 2027 flagship now fixed 6-7 Apr 2027 at Palais des Festivals, Road to Cannes selection model, 2026 jury names). Sponsor variant for sponsor track, organizer variant naming edition ownership and retained sponsorship revenue for organizer track. | Day-11 follow-up sent 2026-09-23, msgid 1a0cdce5dfb2beba. Updated with Cannes 6-7 Apr 2027 + 2027 jury (Agnès Jaoui President).
A30: 2026-09-03 | B30: Harman International (JBL) | C30: Email | D30: indiaprosales@harman.com | E30: indiaprocare@harman.com; david.glaubke@harman.com | F30: WAIFF India x Harman International (JBL) — AI Cinema Partnership | G30: N | H30: N | J30: Y - 2026-09-07 | K30: Y | L30: N | M30: N | O30: Sent | P30: Sent 3 Sep 2026 — Batch 1 (60), Target Batch 2 research. | DAY-4 FOLLOW-UP SENT 7 Sep. Carried genuinely new information: the verified sponsor roster (CapCut/ByteDance, MiniMax, JW Marriott Cannes, LOTTE, Morphic, Skolae) and the official tier benefits, both extracted from the WAiFF deck on 7 Sep. Several were also reframed from sponsor pitch to organizer/jury/masterclass conversation where that fit the company better. || Day 11 follow-up sent 2026-09-14: new-fact angle (Cannes 2027 flagship now fixed 6-7 Apr 2027 at Palais des Festivals, Road to Cannes selection model, 2026 jury names). Sponsor variant for sponsor track, organizer variant naming edition ownership and retained sponsorship revenue for organizer track. | Day-11 follow-up sent 2026-09-23, msgid 1a0cdce64b54c428. Updated with Cannes 6-7 Apr 2027 + 2027 jury (Agnès Jaoui President).
A31: 2026-09-03 | B31: Zebronics | C31: Email | D31: enquiry@zebronics.com | F31: WAIFF India x Zebronics — AI Cinema Partnership | G31: N | H31: N | J31: Y - 2026-09-07 | K31: Y | L31: N | M31: N | O31: Sent | P31: Sent 3 Sep 2026 — Batch 1 (60), Target Batch 2 research. | DAY-4 FOLLOW-UP SENT 7 Sep. Carried genuinely new information: the verified sponsor roster (CapCut/ByteDance, MiniMax, JW Marriott Cannes, LOTTE, Morphic, Skolae) and the official tier benefits, both extracted from the WAiFF deck on 7 Sep. Several were also reframed from sponsor pitch to organizer/jury/masterclass conversation where that fit the company better. || Day 11 follow-up sent 2026-09-14: new-fact angle (Cannes 2027 flagship now fixed 6-7 Apr 2027 at Palais des Festivals, Road to Cannes selection model, 2026 jury names). Sponsor variant for sponsor track, organizer variant naming edition ownership and retained sponsorship revenue for organizer track. | Day-11 follow-up sent 2026-09-23, msgid 1a0cdce6bbe1caa9. Updated with Cannes 6-7 Apr 2027 + 2027 jury (Agnès Jaoui President).
A32: 2026-09-03 | B32: Dell Technologies India | C32: Email | D32: media.relations@dell.com | F32: WAIFF India x Dell Technologies India — AI Cinema Partnership | G32: N | H32: Y | J32: Y - 2026-09-07 | K32: Y - 2026-09-14 | L32: N | M32: N | O32: Replied - Declined | P32: Sent 3 Sep 2026 — Batch 1 (60), Target Batch 2 research. | DAY-4 FOLLOW-UP SENT 7 Sep. Carried genuinely new information: the verified sponsor roster (CapCut/ByteDance, MiniMax, JW Marriott Cannes, LOTTE, Morphic, Skolae) and the official tier benefits, both extracted from the WAiFF deck on 7 Sep. Several were also reframed from sponsor pitch to organizer/jury/masterclass conversation where that fit the company better. || Day 11 follow-up sent 2026-09-14: new-fact angle (Cannes 2027 flagship now fixed 6-7 Apr 2027 at Palais des Festivals, Road to Cannes selection model, 2026 jury names). Sponsor variant for sponsor track, organizer variant naming edition ownership and retained sponsorship revenue for organizer track. || REPLY 2026-09-14: Dell Media Relations declined, won't explore a collaboration at this time.
A33: 2026-09-03 | B33: ASUS India | C33: Email | D33: Media@asus.com | F33: WAIFF India x ASUS India — AI Cinema Partnership | G33: N | H33: N | J33: Y - 2026-09-07 | K33: Y | L33: N | M33: N | O33: Sent | P33: Sent 3 Sep 2026 — Batch 1 (60), Target Batch 2 research. | DAY-4 FOLLOW-UP SENT 7 Sep. Carried genuinely new information: the verified sponsor roster (CapCut/ByteDance, MiniMax, JW Marriott Cannes, LOTTE, Morphic, Skolae) and the official tier benefits, both extracted from the WAiFF deck on 7 Sep. Several were also reframed from sponsor pitch to organizer/jury/masterclass conversation where that fit the company better. || Day 11 follow-up sent 2026-09-14: new-fact angle (Cannes 2027 flagship now fixed 6-7 Apr 2027 at Palais des Festivals, Road to Cannes selection model, 2026 jury names). Sponsor variant for sponsor track, organizer variant naming edition ownership and retained sponsorship revenue for organizer track. | Day-11 follow-up sent 2026-09-23, msgid 1a0cdce72ee3cd67. Updated with Cannes 6-7 Apr 2027 + 2027 jury (Agnès Jaoui President).
A34: 2026-09-03 | B34: Lenovo India | C34: Email | D34: grace.gabel@lenovo.com | E34: sabrina.mohan@lenovo.com; stephanie.yu@lenovo.com | F34: WAIFF India x Lenovo India — AI Cinema Partnership | G34: N | H34: N | J34: Y - 2026-09-07 | K34: Y | L34: N | M34: N | O34: Sent | P34: Sent 3 Sep 2026 — Batch 1 (60), Target Batch 2 research. | DAY-4 FOLLOW-UP SENT 7 Sep. Carried genuinely new information: the verified sponsor roster (CapCut/ByteDance, MiniMax, JW Marriott Cannes, LOTTE, Morphic, Skolae) and the official tier benefits, both extracted from the WAiFF deck on 7 Sep. Several were also reframed from sponsor pitch to organizer/jury/masterclass conversation where that fit the company better. || Day 11 follow-up sent 2026-09-14: new-fact angle (Cannes 2027 flagship now fixed 6-7 Apr 2027 at Palais des Festivals, Road to Cannes selection model, 2026 jury names). Sponsor variant for sponsor track, organizer variant naming edition ownership and retained sponsorship revenue for organizer track. | Day-11 follow-up sent 2026-09-23, msgid 1a0cdce7d5058af6. Updated with Cannes 6-7 Apr 2027 + 2027 jury (Agnès Jaoui President).
