Workbook

Sheet Pipeline Summary
A1: WAIFF India Edition — Outreach Pipeline Summary
A2: Live dashboard, pulled from Targets / Gmail Tracker / LinkedIn Tracker. Update the two blue input cells; everything else recalculates.
A4: SENDING RAMP
A5: Campaign start date | B5: 46265
A6: Days into campaign (today) | B6: =IF($B$5="","",TODAY()-$B$5+1) -> 7
A7: Today's daily send target | B7: =IF($B$5="","",IF((TODAY()-$B$5+1)<=3,25,IF((TODAY()-$B$5+1)<=7,60,IF((TODAY()-$B$5+1)<=14,75,100)))) -> 60
A8: Note (3 Sep 2026): ramp started mid-sequence — Aditya was already sending from his own Gmail, so days 1-3 were skipped. Days 4-7 bumped to 60/day (from the brief's default 50). Days 8-14 and 15+ continue on the original 75 / 100 schedule.
A9: Ramp reference (brief section 8)
A10: Days | B10: Sends/day
A11: Days 1-3 | B11: 25
A12: Days 4-7 | B12: 60
A13: Days 8-14 | B13: 75
A14: Days 15+ | B14: 100
A16: PIPELINE COUNTS (from Targets tab)
A17: Total companies logged | B17: =COUNTA(Targets!$A$5:$A$2000) -> 175
A18: Excluded (section 4) | B18: =COUNTIF(Targets!$O$5:$O$2000,"Excluded") -> 0
A19: Not started | B19: =COUNTIF(Targets!$O$5:$O$2000,"Not started") -> 0
A20: Researching | B20: =COUNTIF(Targets!$O$5:$O$2000,"Researching") -> 0
A21: Ready to send | B21: =COUNTIF(Targets!$O$5:$O$2000,"Ready to send") -> 4
A22: Sent | B22: =COUNTIF(Targets!$O$5:$O$2000,"Sent") -> 154
A23: Replied | B23: =COUNTIF(Targets!$O$5:$O$2000,"Replied") -> 2
A24: Meeting booked | B24: =COUNTIF(Targets!$O$5:$O$2000,"Meeting booked") -> 0
A25: Dormant (past day 25, no response) | B25: =COUNTIF(Targets!$O$5:$O$2000,"Dormant") -> 0
A27: EMAIL / FORM ACTIVITY (from Gmail Tracker tab)
A28: Total companies sent (email + form) | B28: =COUNTA('Gmail Tracker'!$A$5:$A$2000) -> 175
A29: Bounces | B29: =COUNTIF('Gmail Tracker'!$G$5:$G$2000,"Y") -> 9
A30: Bounce rate | B30: =IFERROR(B29/B28,"") -> 0.051428571
A31: Replies | B31: =COUNTIF('Gmail Tracker'!$H$5:$H$2000,"Y") -> 3
A32: Reply rate | B32: =IFERROR(B31/B28,"") -> 0.017142857
A33: Meetings booked | B33: =COUNTIF('Gmail Tracker'!$M$5:$M$2000,"Y") -> 0
A35: LINKEDIN ACTIVITY (from LinkedIn Tracker tab)
A36: Profiles logged (all batches) | B36: =COUNTA('LinkedIn Tracker'!$C$5:$C$2000) -> 131
A37: Connections sent | B37: =COUNTA('LinkedIn Tracker'!$H$5:$H$2000) -> 0
A38: Connections accepted | B38: =COUNTIF('LinkedIn Tracker'!$I$5:$I$2000,"Accepted") -> 0
A39: Accept rate | B39: =IFERROR(B38/B37,"")
A40: Messages sent | B40: =COUNTA('LinkedIn Tracker'!$J$5:$J$2000) -> 0
A41: Replies | B41: =COUNTIF('LinkedIn Tracker'!$K$5:$K$2000,"Y") -> 0
A43: 48-HOUR REVIEW (fill in manually every 2 days — brief section 10c)
A44: Date of review
A45: Best-performing segment
...

Sheet Targets
A1: WAIFF India — Targets (master company list, one row per company)
A2: One-pass rule: each company gets exactly one row. Check for duplicates and section-4 exclusions here before adding. Row 4 is an example only — real rows start at row 5.
A3: Company | B3: Priority Bucket | C3: HQ / Region | D3: Relevance (why qualified) | E3: Capacity check (Y/N/Unknown) | F3: Reachability - named contact found (Y/N) | G3: Excluded? (Y/N) | H3: Exclusion reason | I3: Role target (Sponsor/Organizer/Either) | J3: Best email address | K3: Other addresses (BCC) | L3: Enquiry form URL | M3: Channel chosen | N3: LinkedIn profiles logged? (Y/N) | O3: Status | P3: Date added | Q3: Date first contacted | R3: Follow-up Day 4 done (Y/N) | S3: Follow-up Day 11 done (Y/N) | T3: Follow-up Day 25 done (Y/N) | U3: Notes
A4: Runway AI, Inc. | B4: Venture-funded AI tool company | C4: New York, USA | D4: Makes AI video-generation tools used by filmmakers — direct category fit | E4: Y | F4: Y | G4: N | I4: Sponsor | J4: partnerships@runwayml.com | K4: press@runwayml.com | L4: https://runwayml.com/contact | M4: Email | N4: Y | O4: Researching | P4: 2026-09-03 | R4: N | S4: N | T4: N | U4: EXAMPLE ROW — edit or delete, do not count as real data
A5: Radisson Blu | D5: Already contacted directly by Aditya | E5: Unknown | F5: Unknown | G5: N | I5: Sponsor | J5: communication@radissonhotels.com | M5: Email | N5: N | O5: Replied | P5: 2026-09-01 | Q5: 2026-09-01 | R5: N | S5: N | T5: N | U5: Backfilled 3 Sep 2026 — sent directly by Aditya before this tracker existed. Anuj Kumar asked 3 questions before a call; replied 3 Sep 2026 with company/date/value framing, no deck link sent. Awaiting reply.
A6: EPAM Systems | D6: Already contacted directly by Aditya | E6: Unknown | F6: Unknown | G6: N | I6: Sponsor | K6: sameena.mohdali@gmail.com; sameena_ali@epam.com; nandini_bhatnagar@epam.com; nandinib2007@gmail.com; nandinibhatnagar@epam.it | M6: Email | N6: N | O6: Replied | P6: 2026-09-01 | Q6: 2026-09-01 | R6: N | S6: N | T6: N | U6: Backfilled 3 Sep 2026 — sent directly by Aditya before this tracker existed. Nandini Bhatnagar wants to talk after Sept 9; replied 3 Sep 2026 confirming availability. Awaiting her scheduling reply.
A7: Adani Digital Labs | D7: Already contacted directly by Aditya | E7: Unknown | F7: Unknown | G7: N | I7: Sponsor | K7: digitallabs@adani.com; media@adani.com; hrishik.jethi@adani.com; cgarg@adanidigitallabs.com; manishsingh.payal@adani.com; jaladhi.shukla@adani.com; support@adanione.com; cbccyber1@adani.com | M7: Email | N7: N | O7: Sent | P7: 2026-09-02 | Q7: 2026-09-02 | R7: N | S7: N | T7: N | U7: Backfilled 3 Sep 2026 — sent directly by Aditya before this tracker existed. BOUNCE: 4 of 8 BCC addresses bounced (cgarg@adanidigitallabs.com, hrishik.jethi@adani.com, manishsingh.payal@adani.com, digitallabs@adani.com)
A8: Adani AI Labs | D8: Already contacted directly by Aditya | E8: Unknown | F8: Unknown | G8: N | I8: Sponsor | J8: Shalini.singh@adani.com | K8: roy.paul@adani.com; jeet.adani@adani.com; tanushyam.chattopadhyay@adani.com; investor.ael@adani.com | M8: Email | N8: N | O8: Sent | P8: 2026-09-02 | Q8: 2026-09-02 | R8: N | S8: N | T8: N | U8: Backfilled 3 Sep 2026 — sent directly by Aditya before this tracker existed. BOUNCE: 1 of 4 BCC addresses bounced (tanushyam.chattopadhyay@adani.com); also sent separately to Shalini Singh direct
A9: Freshworks | D9: Already contacted directly by Aditya | E9: Unknown | F9: Unknown | G9: N | I9: Sponsor | K9: sales@freshworks.com; pr@freshworks.com; dpo@freshworks.com; ir@freshworks.com | M9: Email | N9: N | O9: Sent | P9: 2026-09-02 | Q9: 2026-09-02 | R9: N | S9: N | T9: N | U9: Backfilled 3 Sep 2026 — sent directly by Aditya before this tracker existed. Automated support-ticket confirmation only — not a personal reply, no action needed yet
A10: Zoho | D10: Already contacted directly by Aditya | E10: Unknown | F10: Unknown | G10: N | I10: Sponsor | K10: sales@zohocorp.com; partner-operations@zohocorp.com; press@zohocorp.com | M10: Email | N10: N | O10: Sent | P10: 2026-09-02 | Q10: 2026-09-02 | R10: N | S10: N | T10: N | U10: Backfilled 3 Sep 2026 — sent directly by Aditya before this tracker existed. Automated partner-ticket confirmation + generic sales-team reply — not personalized, no action needed yet
A11: Myntra | D11: Already contacted directly by Aditya | E11: Unknown | F11: Unknown | G11: N | I11: Sponsor | J11: communications@myntra.com | M11: Email | N11: N | O11: Bounced | P11: 2026-09-02 | Q11: 2026-09-02 | R11: N | S11: N | T11: N | U11: Backfilled 3 Sep 2026 — sent directly by Aditya before this tracker existed. BOUNCE: Address not found (bounced) — only address used, no BCC alternates
A12: Tech Mahindra | D12: Already contacted directly by Aditya | E12: Unknown | F12: Unknown | G12: N | I12: Sponsor | K12: alliances@techmahindra.com; socialmedia@techmahindra.com; mktg@techmahindra.com; media.relations@techmahindra.com | M12: Email | N12: N | O12: Sent | P12: 2026-09-02 | Q12: 2026-09-02 | R12: N | S12: N | T12: N | U12: Backfilled 3 Sep 2026 — sent directly by Aditya before this tracker existed.
A13: BenQ India | D13: Already contacted directly by Aditya | E13: Unknown | F13: Unknown | G13: N | I13: Sponsor | K13: ruchika.singh@benq.com; ankita.karwa@benq.com; rajeev.singh@benq.com (+3 personal-looking gmail addresses also BCC'd) | M13: Email | N13: N | O13: Sent | P13: 2026-09-02 | Q13: 2026-09-02 | R13: N | S13: N | T13: N | U13: Backfilled 3 Sep 2026 — sent directly by Aditya before this tracker existed.
A14: Sennheiser | D14: Already contacted directly by Aditya | E14: Unknown | F14: Unknown | G14: N | I14: Sponsor | K14: sponsoring@sennheiser.com; sarah.talaat@sennheiser.com; felix.teufel@sennheiser.com (+17 more BCC'd, incl. Sonova/Neumann/agency addresses) | M14: Email | N14: N | O14: Sent | P14: 2026-09-02 | Q14: 2026-09-02 | R14: N | S14: N | T14: N | U14: Backfilled 3 Sep 2026 — sent directly by Aditya before this tracker existed.
A15: Runway | B15: Venture-funded AI tool company | C15: San Francisco, US | D15: Gen-4.5 launch + Lionsgate equity partnership for AI-generated franchise content | E15: Y | F15: Y | G15: N | I15: Sponsor | J15: partnerships@runwayml.com | K15: press@runwayml.com | M15: Email | N15: N | O15: Sent | P15: 2026-09-03 | Q15: 2026-09-03 | R15: N | S15: N | T15: N | U15: Sent 3 Sep 2026 — Batch 1 (60), Target Batch 2 research.
A16: Genmo | B16: Venture-funded AI tool company | C16: San Francisco, US | D16: Mochi 1 open text-to-video model, still updated a year on | E16: Y | F16: Y | G16: N | I16: Sponsor | J16: hi@genmo.ai | M16: Email | N16: N | O16: Sent | P16: 2026-09-03 | Q16: 2026-09-03 | R16: N | S16: N | T16: N | U16: Sent 3 Sep 2026 — Batch 1 (60), Target Batch 2 research.
A17: Shengshu Technology (Vidu) | B17: Venture-funded AI tool company | C17: Beijing, China | D17: Alibaba Cloud $290M round backing Vidu world-model ambitions | E17: Y | F17: Y | G17: N | I17: Sponsor | J17: support@vidu.com | M17: Email | N17: N | O17: Sent | P17: 2026-09-03 | Q17: 2026-09-03 | R17: N | S17: N | T17: N | U17: Sent 3 Sep 2026 — Batch 1 (60), Target Batch 2 research.
A18: ElevenLabs | B18: Venture-funded AI tool company | C18: London, UK | D18: New CRO, Canada launch, CLI v1 release | E18: Y | F18: Y | G18: N | I18: Sponsor | J18: press@elevenlabs.io | M18: Email | N18: N | O18: Sent | P18: 2026-09-03 | Q18: 2026-09-03 | R18: N | S18: N | T18: N | U18: Sent 3 Sep 2026 — Batch 1 (60), Target Batch 2 research.
A19: Murf AI | B19: Venture-funded AI tool company | C19: Bangalore, India | D19: 300+ Forbes 2000 clients, 6M+ users, 20+ languages | E19: Y | F19: Y | G19: N | I19: Sponsor | J19: alliances@murf.ai | K19: enterprise@murf.ai; support@murf.ai | M19: Email | N19: N | O19: Sent | P19: 2026-09-03 | Q19: 2026-09-03 | R19: N | S19: N | T19: N | U19: Sent 3 Sep 2026 — Batch 1 (60), Target Batch 2 research.
A20: NeuralGarage | B20: Venture-funded AI tool company | C20: Mumbai, India | D20: VisualDub — SXSW 2025 winner, lip-sync tech used in Rajinikanth's Coolie | E20: Y | F20: Y | G20: N | I20: Sponsor | J20: info@neuralgarage.com | M20: Email | N20: N | O20: Sent | P20: 2026-09-03 | Q20: 2026-09-03 | R20: N | S20: N | T20: N | U20: Sent 3 Sep 2026 — Batch 1 (60), Target Batch 2 research.
A21: Synthesia | B21: Venture-funded AI tool company | C21: London, UK | D21: Signed EU Article 50 AI Act code of practice; interactive AI press-officer avatar | E21: Y | F21: Y | G21: N | I21: Sponsor | J21: press@synthesia.io | M21: Email | N21: N | O21: Sent | P21: 2026-09-03 | Q21: 2026-09-03 | R21: N | S21: N | T21: N | U21: Sent 3 Sep 2026 — Batch 1 (60), Target Batch 2 research.
A22: OpusClip (Opus.pro) | B22: Venture-funded AI tool company | C22: San Francisco, US | D22: SoftBank Vision Fund 2 $20M investment in AI video editing platform | E22: Y | F22: Y | G22: N | I22: Sponsor | J22: contact@opus.pro | M22: Email | N22: N | O22: Sent | P22: 2026-09-03 | Q22: 2026-09-03 | R22: N | S22: N | T22: N | U22: Sent 3 Sep 2026 — Batch 1 (60), Target Batch 2 research.
A23: Captions (Mirage) | B23: Venture-funded AI tool company | C23: New York, US | D23: $75M raise from General Catalyst Customer Value Fund for Asia expansion | E23: Y | F23: Y | G23: N | I23: Sponsor | J23: press@mirage.app | K23: info@mirage.app | M23: Email | N23: N | O23: Sent | P23: 2026-09-03 | Q23: 2026-09-03 | R23: N | S23: N | T23: N | U23: Sent 3 Sep 2026 — Batch 1 (60), Target Batch 2 research.
A24: Topaz Labs | B24: Venture-funded AI tool company | C24: Dallas, US | D24: Largest single AI model release in company history; NeuroStream cuts VRAM 95% | E24: Y | F24: Y | G24: N | I24: Sponsor | J24: Press@topazlabs.com | M24: Email | N24: N | O24: Sent | P24: 2026-09-03 | Q24: 2026-09-03 | R24: N | S24: N | T24: N | U24: Sent 3 Sep 2026 — Batch 1 (60), Target Batch 2 research.
A25: Black Forest Labs | B25: Venture-funded AI tool company | C25: Freiburg, Germany | D25: Martin Scorsese joined as advisor to shape FLUX use in filmmaking pre-production | E25: Y | F25: Y | G25: N | I25: Sponsor | J25: info@blackforestlabs.ai | M25: Email | N25: N | O25: Sent | P25: 2026-09-03 | Q25: 2026-09-03 | R25: N | S25: N | T25: N | U25: Sent 3 Sep 2026 — Batch 1 (60), Target Batch 2 research.
A26: Stability AI | B26: Venture-funded AI tool company | C26: London, UK | D26: $76M Series B backed by EA/Sony Music/UMG/WMG/AMD Ventures + new WPP partnership | E26: Y | F26: Y | G26: N | I26: Sponsor | J26: partners@stability.ai | K26: press@stability.ai | M26: Email | N26: N | O26: Sent | P26: 2026-09-03 | Q26: 2026-09-03 | R26: N | S26: N | T26: N | U26: Sent 3 Sep 2026 — Batch 1 (60), Target Batch 2 research.
A27: NVIDIA | B27: India-operating hardware & consumer brand | C27: Santa Clara, US (India: Bengaluru/Gurugram) | D27: Cosmos 3 Edge world model + Synthetic Video Detector NIM announced at SIGGRAPH 2026 | E27: Y | F27: Y | G27: N | I27: Sponsor | J27: india-pr@nvidia.com | M27: Email | N27: N | O27: Sent | P27: 2026-09-03 | Q27: 2026-09-03 | R27: N | S27: N | T27: N | U27: Sent 3 Sep 2026 — Batch 1 (60), Target Batch 2 research.
A28: Qualcomm | B28: India-operating hardware & consumer brand | C28: San Diego, US (India offices) | D28: "Snapdragon For India 2026" launch of Snapdragon 6 Gen 5 / 4 Gen 5 | E28: Y | F28: Y | G28: N | I28: Sponsor | J28: corpcomm@qualcomm.com | M28: Email | N28: N | O28: Sent | P28: 2026-09-03 | Q28: 2026-09-03 | R28: N | S28: N | T28: N | U28: Sent 3 Sep 2026 — Batch 1 (60), Target Batch 2 research.
A29: Sony India | B29: India-operating hardware & consumer brand | C29: Tokyo, Japan (India subsidiary) | D29: ILCE-7V launch with AI-powered Auto Framing and 7K-oversampled 4K/60p video | E29: Y | F29: Y | G29: N | I29: Sponsor | J29: press.india@sony.com | M29: Email | N29: N | O29: Sent | P29: 2026-09-03 | Q29: 2026-09-03 | R29: N | S29: N | T29: N | U29: Sent 3 Sep 2026 — Batch 1 (60), Target Batch 2 research.
A30: Harman International (JBL) | B30: India-operating hardware & consumer brand | C30: Stamford, US (India office; Samsung-owned) | D30: JBL 80th anniversary; Summit Everest / Summit K2 loudspeaker launch | E30: Y | F30: Y | G30: N | I30: Sponsor | J30: indiaprosales@harman.com | K30: indiaprocare@harman.com; david.glaubke@harman.com | M30: Email | N30: N | O30: Sent | P30: 2026-09-03 | Q30: 2026-09-03 | R30: N | S30: N | T30: N | U30: Sent 3 Sep 2026 — Batch 1 (60), Target Batch 2 research.
A31: Zebronics | B31: India-operating hardware & consumer brand | C31: Chennai, India | D31: Zeb-PixaPlay 72 Plus — 120-inch, 4000-lumen smart projector | E31: Y | F31: Y | G31: N | I31: Sponsor | J31: enquiry@zebronics.com | M31: Email | N31: N | O31: Sent | P31: 2026-09-03 | Q31: 2026-09-03 | R31: N | S31: N | T31: N | U31: Sent 3 Sep 2026 — Batch 1 (60), Target Batch 2 research.
A32: Dell Technologies India | B32: India-operating hardware & consumer brand | C32: Round Rock, US (India: Bengaluru/Hyderabad) | D32: Alienware 16X Aurora "Back to School" campaign with Jemimah Rodrigues and Yashraj Mukhate | E32: Y | F32: Y | G32: N | I32: Sponsor | J32: media.relations@dell.com | M32: Email | N32: N | O32: Sent | P32: 2026-09-03 | Q32: 2026-09-03 | R32: N | S32: N | T32: N | U32: Sent 3 Sep 2026 — Batch 1 (60), Target Batch 2 research.
A33: ASUS India | B33: India-operating hardware & consumer brand | C33: Taipei, Taiwan (India subsidiary) | D33: ROG Flow Z13 Kojima Productions Edition collab (Death Stranding universe) | E33: Y | F33: Y | G33: N | I33: Sponsor | J33: Media@asus.com | M33: Email | N33: N | O33: Sent | P33: 2026-09-03 | Q33: 2026-09-03 | R33: N | S33: N | T33: N | U33: Sent 3 Sep 2026 — Batch 1 (60), Target Batch 2 research.
A34: Lenovo India | B34: India-operating hardware & consumer brand | C34: Beijing/Morrisville (India subsidiary) | D34: Creator/influencer partnerships program (Grace Gabel, Sabrina Mohan) | E34: Y | F34: Y | G34: N | I34: Sponsor | J34: grace.gabel@lenovo.com | K34: sabrina.mohan@lenovo.com; stephanie.yu@lenovo.com | M34: Email | N34: N | O34: Sent | P34: 2026-09-03 | Q34: 2026-09-03 | R34: N | S34: N | T34: N | U34: Sent 3 Sep 2026 — Batch 1 (60), Target Batch 2 research.
A35: Western Digital (SanDisk Professional) | B35: India-operating hardware & consumer brand | C35: San Jose, US (India operations) | D35: SanDisk Creator Series launch in India for 4K-6K creators, bundled Adobe CC trial | E35: Y | F35: Y | G35: N | I35: Sponsor | J35: WD.Mediainquiries@wdc.com | M35: Email | N35: N | O35: Sent | P35: 2026-09-03 | Q35: 2026-09-03 | R35: N | S35: N | T35: N | U35: Sent 3 Sep 2026 — Batch 1 (60), Target Batch 2 research.
A36: Samsung India | B36: India-operating hardware & consumer brand | C36: Suwon, South Korea (India subsidiary) | D36: Brut India partnership covering 2026 Cannes red carpet via Galaxy S26 Ultra creator storytelling | E36: Y | F36: Y | G36: N | I36: Sponsor | J36: corpcommindia@samsung.com | M36: Email | N36: N | O36: Sent | P36: 2026-09-03 | Q36: 2026-09-03 | R36: N | S36: N | T36: N | U36: Sent 3 Sep 2026 — Batch 1 (60), Target Batch 2 research.
A37: Krutrim AI (Ola Krutrim) | B37: Indian AI infrastructure | C37: Bengaluru, India | D37: First annual net profit; revenue nearly tripled; 25+ enterprise clients | E37: Y | F37: Y | G37: N | I37: Sponsor | J37: sales@olakrutrim.com | K37: cloudsupport@olakrutrim.com | M37: Email | N37: N | O37: Sent | P37: 2026-09-03 | Q37: 2026-09-03 | R37: N | S37: N | T37: N | U37: Sent 3 Sep 2026 — Batch 1 (60), Target Batch 2 research.
A38: Yotta Data Services | B38: Indian AI infrastructure | C38: Navi Mumbai, India | D38: Frost & Sullivan 2026 Indian Company of the Year for Sovereign AI Infrastructure | E38: Y | F38: Y | G38: N | I38: Sponsor | J38: marketing@yotta.com | K38: info@yotta.com | M38: Email | N38: N | O38: Sent | P38: 2026-09-03 | Q38: 2026-09-03 | R38: N | S38: N | T38: N | U38: Sent 3 Sep 2026 — Batch 1 (60), Target Batch 2 research.
A39: E2E Networks | B39: Indian AI infrastructure | C39: New Delhi, India | D39: ₹1,000 crore Blackwell GPU order + new NVIDIA B200 cluster on TIR platform | E39: Y | F39: Y | G39: N | I39: Sponsor | J39: sales@e2enetworks.com | M39: Email | N39: N | O39: Sent | P39: 2026-09-03 | Q39: 2026-09-03 | R39: N | S39: N | T39: N | U39: Sent 3 Sep 2026 — Batch 1 (60), Target Batch 2 research.
A40: Netweb Technologies | B40: Indian AI infrastructure | C40: Faridabad, India | D40: Launched Tyrone ParallelStor Velox unified data platform for AI/HPC | E40: Y | F40: Y | G40: N | I40: Sponsor | J40: mktkol@netwebindia.com | K40: info@netwebindia.com; hydsales@netwebindia.com | M40: Email | N40: N | O40: Sent | P40: 2026-09-03 | Q40: 2026-09-03 | R40: N | S40: N | T40: N | U40: Sent 3 Sep 2026 — Batch 1 (60), Target Batch 2 research.
...

Sheet LinkedIn Tracker
A1: WAIFF India — LinkedIn Tracker (80 profiles/week, one dated batch at a time)
A2: Source only from companies already in the email batch — no separate LinkedIn universe. No repeats, ever. Row 4 is an example only.
A3: Batch # | B3: Batch date | C3: Name | D3: Title | E3: Company | F3: Profile URL | G3: Sourced from an email-batch company? (Y/N) | H3: Connection sent date | I3: Connection status | J3: Message sent date | K3: Reply? (Y/N) | L3: Reply date | M3: Follow-up date | N3: Notes
A4: 1 | B4: 2026-09-03 | C4: Jane Doe | D4: Head of Partnerships | E4: Runway AI, Inc. | F4: https://www.linkedin.com/in/example-profile | G4: Y | I4: Pending | K4: N | N4: EXAMPLE ROW — edit or delete, do not count as real data
A5: 1 | B5: 2026-09-03 | C5: Michelle Kwon | D5: Head of Operations and Partnerships | E5: Runway | F5: https://www.linkedin.com/in/michelleskwon/ | G5: Y | I5: Pending | K5: N | N5: Connection note: Hi Michelle, following Runway's Gen-4.5 and the Lionsgate deal closely. I'm building the founding sponsor group for WAiFF's India edition, launching December 2026. Would love to connect.
A6: 1 | B6: 2026-09-03 | C6: Tony Pu | D6: Community & Partnerships | E6: Kuaishou / Kling AI | F6: https://www.linkedin.com/in/tpu0817/ | G6: Y | I6: Pending | K6: N | N6: Connection note: Hi Tony, Kling AI's growth this year has been remarkable. I'm the India Ambassador for WAiFF, the AI film festival held at Cannes, building our India sponsor group. Would love to connect.
A7: 1 | B7: 2026-09-03 | C7: Paras Jain | D7: Genmo (title unconfirmed) | E7: Genmo | F7: https://www.linkedin.com/in/jain-paras/ | G7: Y | I7: Pending | K7: N | N7: Connection note: Hi Paras, Mochi 1's open approach to text-to-video stood out to me. I'm building the founding sponsor group for WAiFF India, launching December 2026. Would love to connect.
A8: 1 | B8: 2026-09-03 | C8: Franz-Josef Schrepf | D8: Revenue & Partnerships | E8: OpusClip | F8: https://www.linkedin.com/in/franz-josef-schrepf/ | G8: Y | I8: Pending | K8: N | N8: Connection note: Hi Franz-Josef, congrats on the SoftBank Vision Fund 2 investment. I'm the India Ambassador for WAiFF, the AI film festival at Cannes, building our India sponsor group. Would love to connect.
A9: 1 | B9: 2026-09-03 | C9: Callie Costello | D9: Product & Brand Marketing | E9: Mirage (Captions) | F9: https://www.linkedin.com/in/calliegcostello/ | G9: Y | I9: Pending | K9: N | N9: Connection note: Hi Callie, congrats on the $75M raise and the Asia expansion. I'm building the founding sponsor group for WAiFF's India edition, launching December 2026. Would love to connect.
A10: 1 | B10: 2026-09-03 | C10: Ross Shain | D10: Principal Creative Technologist | E10: Topaz Labs | F10: https://www.linkedin.com/in/rshain/ | G10: Y | I10: Pending | K10: N | N10: Connection note: Hi Ross, the Next-Gen model launch and NeuroStream tech are impressive. I'm the India Ambassador for WAiFF, the AI film festival at Cannes, building our India sponsor group. Would love to connect.
A11: 1 | B11: 2026-09-03 | C11: Michelle Belcic | D11: VP Sales & Partnerships | E11: Photoroom | F11: https://fr.linkedin.com/in/michellebelcic | G11: Y | I11: Pending | K11: N | N11: Connection note: Hi Michelle, Photoroom's H1 2026 product recap was impressive. I'm building the founding sponsor group for WAiFF's India edition, launching December 2026. Would love to connect.
A12: 1 | B12: 2026-09-03 | C12: Anthony Ganjou | D12: Co-Founder | E12: Move AI | F12: https://www.linkedin.com/in/anthonyganjou/ | G12: Y | I12: Pending | K12: N | N12: Connection note: Hi Anthony, Move AI's marker-less mocap work with studios like Disney and Paramount is exactly the kind of tool WAiFF's filmmakers need. Building our India sponsor group. Would love to connect.
A13: 1 | B13: 2026-09-03 | C13: Sofía Goble | D13: Operations (unconfirmed current role) | E13: Cuebric | F13: https://www.linkedin.com/in/sof%C3%ADa-goble-17a56a1a3/ | G13: Y | I13: Pending | K13: N | N13: Connection note: Hi Sofía, Cuebric's virtual-production work with Disguise caught my eye. I'm building the founding sponsor group for WAiFF's India edition, launching December 2026. Would love to connect.
A14: 1 | B14: 2026-09-03 | C14: Parthajit Sar | D14: Marketing programs | E14: NVIDIA | F14: https://in.linkedin.com/in/parthajit-sar | G14: Y | I14: Pending | K14: N | N14: Connection note: Hi Parthajit, NVIDIA's Cosmos 3 Edge announcement at SIGGRAPH was a big one for AI filmmaking. I'm building WAiFF's India sponsor group, launching December 2026. Would love to connect.
A15: 1 | B15: 2026-09-03 | C15: Vishal Dhupar | D15: Managing Director, Asia South | E15: NVIDIA | F15: https://in.linkedin.com/in/vishaldhupar | G15: Y | I15: Pending | K15: N | N15: Connection note: Hi Vishal, I'm the India Ambassador for WAiFF, the AI film festival held at Cannes, building our founding India sponsor group launching December 2026. Would love to connect.
... A135: 4 | B135: 2026-09-03 | C135: Colan Sewell | D135: VP, Chief Revenue Officer, Reality Labs | E135: Meta | F135: https://www.linkedin.com/in/colansewell/ | G135: Y | I135: Pending | K135: N | N135: Most senior revenue/partnerships executive in Reality Labs.

Sheet Gmail Tracker
A1: WAIFF India — Gmail Tracker (one send per company)
A2: One body per company: best address in To:, other addresses at that same company in BCC. Never BCC across different companies. Row 4 is an example only.
A3: Date sent | B3: Company | C3: Channel | D3: To address | E3: BCC addresses | F3: Subject line | G3: Bounced? (Y/N) | H3: Reply received? (Y/N) | I3: Reply date | J3: Follow-up Day 4 sent (Y/N) | K3: Follow-up Day 11 sent (Y/N) | L3: Follow-up Day 25 sent (Y/N) | M3: Meeting booked? (Y/N) | N3: Meeting date | O3: Status | P3: Notes
A4: 2026-09-01 | B4: Radisson Blu | C4: Email | D4: communication@radissonhotels.com | F4: Partnership Opportunity with WAIFF India — Radisson Blu x World AI Film Festival | G4: N | H4: Y | I4: 2026-09-02 | J4: N | K4: N | L4: N | M4: N | O4: Replied | P4: Sent before this tracker existed — backfilled from Gmail search 3 Sep 2026. Anuj Kumar (Marketing Manager, South Asia) asked 3 specific questions before a call. Replied 3 Sep 2026: covered India edition (Dec 2026, Mumbai), JW Marriott Cannes as existing global sponsor, what Radisson gets (network-wide visibility, access, association) and what WAiFF needs (VIP accommodation/hosting, brand partner role, not just venue). No Canva/deck link sent per standing rule. Asked for a call after 2 PM IST. Awaiting reply.
A5: 2026-09-01 | B5: EPAM Systems | C5: Email | D5: (BCC only — see BCC column) | E5: sameena.mohdali@gmail.com; sameena_ali@epam.com; nandini_bhatnagar@epam.com; nandinib2007@gmail.com; nandinibhatnagar@epam.it | F5: Partnership Opportunity with WAIFF India — EPAM Systems x World AI Film Festival | G5: N | H5: Y | I5: 2026-09-02 | J5: N | K5: N | L5: N | M5: N | O5: Replied | P5: Sent before this tracker existed — backfilled from Gmail search 3 Sep 2026. Nandini Bhatnagar (Sr Director Marketing) wants to talk after Sept 9. Replied 3 Sep 2026 confirming availability anytime after 12:00 PM IST, around 4:00 PM IST or later. Awaiting her scheduling reply.
A6: 2026-09-02 | B6: Adani Digital Labs | C6: Email | D6: (BCC only — see BCC column) | E6: digitallabs@adani.com; media@adani.com; hrishik.jethi@adani.com; cgarg@adanidigitallabs.com; manishsingh.payal@adani.com; jaladhi.shukla@adani.com; support@adanione.com; cbccyber1@adani.com | F6: Partnership Opportunity with WAIFF India — Adani Digital Labs x World AI Film Festival | G6: Y | H6: N | J6: N | K6: N | L6: N | M6: N | O6: Bounced | P6: Sent before this tracker existed — backfilled from Gmail search 3 Sep 2026. BOUNCE: 4 of 8 BCC addresses bounced (cgarg@adanidigitallabs.com, hrishik.jethi@adani.com, manishsingh.payal@adani.com, digitallabs@adani.com)
A7: 2026-09-02 | B7: Adani AI Labs | C7: Email | D7: Shalini.singh@adani.com | E7: roy.paul@adani.com; jeet.adani@adani.com; tanushyam.chattopadhyay@adani.com; investor.ael@adani.com | F7: Partnership Opportunity with WAIFF India — Adani AI Labs x World AI Film Festival | G7: Y | H7: N | J7: N | K7: N | L7: N | M7: N | O7: Bounced | P7: Sent before this tracker existed — backfilled from Gmail search 3 Sep 2026. BOUNCE: 1 of 4 BCC addresses bounced (tanushyam.chattopadhyay@adani.com); also sent separately to Shalini Singh direct
A8: 2026-09-02 | B8: Freshworks | C8: Email | D8: (BCC only — see BCC column) | E8: sales@freshworks.com; pr@freshworks.com; dpo@freshworks.com; ir@freshworks.com | F8: Partnership Opportunity with WAIFF India — Freshworks x World AI Film Festival | G8: N | H8: Y | I8: 2026-09-02 | J8: N | K8: N | L8: N | M8: N | O8: Sent | P8: Sent before this tracker existed — backfilled from Gmail search 3 Sep 2026. Automated support-ticket confirmation only — not a personal reply, no action needed yet
A9: 2026-09-02 | B9: Zoho | C9: Email | D9: (BCC only — see BCC column) | E9: sales@zohocorp.com; partner-operations@zohocorp.com; press@zohocorp.com | F9: Partnership Opportunity with WAIFF India — Zoho x World AI Film Festival | G9: N | H9: Y | I9: 2026-09-02 | J9: N | K9: N | L9: N | M9: N | O9: Sent | P9: Sent before this tracker existed — backfilled from Gmail search 3 Sep 2026. Automated partner-ticket confirmation + generic sales-team reply — not personalized, no action needed yet
A10: 2026-09-02 | B10: Myntra | C10: Email | D10: communications@myntra.com | F10: Partnership Opportunity with WAIFF India — Myntra x World AI Film Festival | G10: Y | H10: N | J10: N | K10: N | L10: N | M10: N | O10: Bounced | P10: Sent before this tracker existed — backfilled from Gmail search 3 Sep 2026. BOUNCE: Address not found (bounced) — only address used, no BCC alternates
A11: 2026-09-02 | B11: Tech Mahindra | C11: Email | D11: (BCC only — see BCC column) | E11: alliances@techmahindra.com; socialmedia@techmahindra.com; mktg@techmahindra.com; media.relations@techmahindra.com | F11: Partnership Opportunity with WAIFF India — Tech Mahindra x World AI Film Festival | G11: N | H11: N | J11: N | K11: N | L11: N | M11: N | O11: Sent | P11: Sent before this tracker existed — backfilled from Gmail search 3 Sep 2026.
A12: 2026-09-02 | B12: BenQ India | C12: Email | D12: (BCC only — see BCC column) | E12: ruchika.singh@benq.com; ankita.karwa@benq.com; rajeev.singh@benq.com (+3 personal-looking gmail addresses also BCC'd) | F12: Partnership Opportunity with WAIFF India — BenQ India x World AI Film Festival | G12: N | H12: N | J12: N | K12: N | L12: N | M12: N | O12: Sent | P12: Sent before this tracker existed — backfilled from Gmail search 3 Sep 2026.
A13: 2026-09-02 | B13: Sennheiser | C13: Email | D13: (BCC only — see BCC column) | E13: sponsoring@sennheiser.com; sarah.talaat@sennheiser.com; felix.teufel@sennheiser.com (+17 more BCC'd, incl. Sonova/Neumann/agency addresses) | F13: Partnership Opportunity with WAIFF India — Sennheiser x World AI Film Festival | G13: N | H13: N | J13: N | K13: N | L13: N | M13: N | O13: Sent | P13: Sent before this tracker existed — backfilled from Gmail search 3 Sep 2026.
A14: 2026-09-03 | B14: Runway AI, Inc. | C14: Email | D14: partnerships@runwayml.com | E14: press@runwayml.com | F14: Partnering with WAiFF India — Runway x World AI Film Festival | G14: N | H14: N | J14: N | K14: N | L14: N | M14: N | O14: Sent | P14: Real send, confirmed via Gmail — landed clean, no bounce, no reply yet.
A15: 2026-09-03 | B15: Runway | C15: Email | D15: partnerships@runwayml.com | E15: press@runwayml.com | F15: WAIFF India x Runway — AI Cinema Partnership | G15: N | H15: N | J15: N | K15: N | L15: N | M15: N | O15: Sent | P15: Sent 3 Sep 2026 — Batch 1 (60), Target Batch 2 research.
A16: 2026-09-03 | B16: Genmo | C16: Email | D16: hi@genmo.ai | F16: WAIFF India x Genmo — AI Cinema Partnership | G16: N | H16: N | J16: N | K16: N | L16: N | M16: N | O16: Sent | P16: Sent 3 Sep 2026 — Batch 1 (60), Target Batch 2 research.
A17: 2026-09-03 | B17: Shengshu Technology (Vidu) | C17: Email | D17: support@vidu.com | F17: WAIFF India x Shengshu Technology (Vidu) — AI Cinema Partnership | G17: N | H17: N | J17: N | K17: N | L17: N | M17: N | O17: Sent | P17: Sent 3 Sep 2026 — Batch 1 (60), Target Batch 2 research.
A18: 2026-09-03 | B18: ElevenLabs | C18: Email | D18: press@elevenlabs.io | F18: WAIFF India x ElevenLabs — AI Cinema Partnership | G18: N | H18: N | J18: N | K18: N | L18: N | M18: N | O18: Sent | P18: Sent 3 Sep 2026 — Batch 1 (60), Target Batch 2 research.
A19: 2026-09-03 | B19: Murf AI | C19: Email | D19: alliances@murf.ai | E19: enterprise@murf.ai; support@murf.ai | F19: WAIFF India x Murf AI — AI Cinema Partnership | G19: N | H19: N | J19: N | K19: N | L19: N | M19: N | O19: Sent | P19: Sent 3 Sep 2026 — Batch 1 (60), Target Batch 2 research.
A20: 2026-09-03 | B20: NeuralGarage | C20: Email | D20: info@neuralgarage.com | F20: WAIFF India x NeuralGarage — AI Cinema Partnership | G20: N | H20: N | J20: N | K20: N | L20: N | M20: N | O20: Sent | P20: Sent 3 Sep 2026 — Batch 1 (60), Target Batch 2 research.
A21: 2026-09-03 | B21: Synthesia | C21: Email | D21: press@synthesia.io | F21: WAIFF India x Synthesia — AI Cinema Partnership | G21: N | H21: N | J21: N | K21: N | L21: N | M21: N | O21: Sent | P21: Sent 3 Sep 2026 — Batch 1 (60), Target Batch 2 research.
A22: 2026-09-03 | B22: OpusClip (Opus.pro) | C22: Email | D22: contact@opus.pro | F22: WAIFF India x OpusClip (Opus.pro) — AI Cinema Partnership | G22: N | H22: N | J22: N | K22: N | L22: N | M22: N | O22: Sent | P22: Sent 3 Sep 2026 — Batch 1 (60), Target Batch 2 research.
A23: 2026-09-03 | B23: Captions (Mirage) | C23: Email | D23: press@mirage.app | E23: info@mirage.app | F23: WAIFF India x Captions (Mirage) — AI Cinema Partnership | G23: N | H23: N | J23: N | K23: N | L23: N | M23: N | O23: Sent | P23: Sent 3 Sep 2026 — Batch 1 (60), Target Batch 2 research.
A24: 2026-09-03 | B24: Topaz Labs | C24: Email | D24: Press@topazlabs.com | F24: WAIFF India x Topaz Labs — AI Cinema Partnership | G24: N | H24: N | J24: N | K24: N | L24: N | M24: N | O24: Sent | P24: Sent 3 Sep 2026 — Batch 1 (60), Target Batch 2 research.
A25: 2026-09-03 | B25: Black Forest Labs | C25: Email | D25: info@blackforestlabs.ai | F25: WAIFF India x Black Forest Labs — AI Cinema Partnership | G25: N | H25: N | J25: N | K25: N | L25: N | M25: N | O25: Sent | P25: Sent 3 Sep 2026 — Batch 1 (60), Target Batch 2 research.
A26: 2026-09-03 | B26: Stability AI | C26: Email | D26: partners@stability.ai | E26: press@stability.ai | F26: WAIFF India x Stability AI — AI Cinema Partnership | G26: N | H26: N | J26: N | K26: N | L26: N | M26: N | O26: Sent | P26: Sent 3 Sep 2026 — Batch 1 (60), Target Batch 2 research.
A27: 2026-09-03 | B27: NVIDIA | C27: Email | D27: india-pr@nvidia.com | F27: WAIFF India x NVIDIA — AI Cinema Partnership | G27: N | H27: N | J27: N | K27: N | L27: N | M27: N | O27: Sent | P27: Sent 3 Sep 2026 — Batch 1 (60), Target Batch 2 research.
A28: 2026-09-03 | B28: Qualcomm | C28: Email | D28: corpcomm@qualcomm.com | F28: WAIFF India x Qualcomm — AI Cinema Partnership | G28: N | H28: N | J28: N | K28: N | L28: N | M28: N | O28: Sent | P28: Sent 3 Sep 2026 — Batch 1 (60), Target Batch 2 research.
A29: 2026-09-03 | B29: Sony India | C29: Email | D29: press.india@sony.com | F29: WAIFF India x Sony India — AI Cinema Partnership | G29: N | H29: N | J29: N | K29: N | L29: N | M29: N | O29: Sent | P29: Sent 3 Sep 2026 — Batch 1 (60), Target Batch 2 research.
A30: 2026-09-03 | B30: Harman International (JBL) | C30: Email | D30: indiaprosales@harman.com | E30: indiaprocare@harman.com; david.glaubke@harman.com | F30: WAIFF India x Harman International (JBL) — AI Cinema Partnership | G30: N | H30: N | J30: N | K30: N | L30: N | M30: N | O30: Sent | P30: Sent 3 Sep 2026 — Batch 1 (60), Target Batch 2 research.
A31: 2026-09-03 | B31: Zebronics | C31: Email | D31: enquiry@zebronics.com | F31: WAIFF India x Zebronics — AI Cinema Partnership | G31: N | H31: N | J31: N | K31: N | L31: N | M31: N | O31: Sent | P31: Sent 3 Sep 2026 — Batch 1 (60), Target Batch 2 research.
A32: 2026-09-03 | B32: Dell Technologies India | C32: Email | D32: media.relations@dell.com | F32: WAIFF India x Dell Technologies India — AI Cinema Partnership | G32: N | H32: N | J32: N | K32: N | L32: N | M32: N | O32: Sent | P32: Sent 3 Sep 2026 — Batch 1 (60), Target Batch 2 research.
A33: 2026-09-03 | B33: ASUS India | C33: Email | D33: Media@asus.com | F33: WAIFF India x ASUS India — AI Cinema Partnership | G33: N | H33: N | J33: N | K33: N | L33: N | M33: N | O33: Sent | P33: Sent 3 Sep 2026 — Batch 1 (60), Target Batch 2 research.
A34: 2026-09-03 | B34: Lenovo India | C34: Email | D34: grace.gabel@lenovo.com | E34: sabrina.mohan@lenovo.com; stephanie.yu@lenovo.com | F34: WAIFF India x Lenovo India — AI Cinema Partnership | G34: N | H34: N | J34: N | K34: N | L34: N | M34: N | O34: Sent | P34: Sent 3 Sep 2026 — Batch 1 (60), Target Batch 2 research.
A35: 2026-09-03 | B35: Western Digital (SanDisk Professional) | C35: Email | D35: WD.Mediainquiries@wdc.com | F35: WAIFF India x Western Digital (SanDisk Professional) — AI Cinema Partnership | G35: N | H35: N | J35: N | K35: N | L35: N | M35: N | O35: Sent | P35: Sent 3 Sep 2026 — Batch 1 (60), Target Batch 2 research.
A36: 2026-09-03 | B36: Samsung India | C36: Email | D36: corpcommindia@samsung.com | F36: WAIFF India x Samsung India — AI Cinema Partnership | G36: N | H36: N | J36: N | K36: N | L36: N | M36: N | O36: Sent | P36: Sent 3 Sep 2026 — Batch 1 (60), Target Batch 2 research.
A37: 2026-09-03 | B37: Krutrim AI (Ola Krutrim) | C37: Email | D37: sales@olakrutrim.com | E37: cloudsupport@olakrutrim.com | F37: WAIFF India x Krutrim AI (Ola Krutrim) — AI Cinema Partnership | G37: N | H37: N | J37: N | K37: N | L37: N | M37: N | O37: Sent | P37: Sent 3 Sep 2026 — Batch 1 (60), Target Batch 2 research.
A38: 2026-09-03 | B38: Yotta Data Services | C38: Email | D38: marketing@yotta.com | E38: info@yotta.com | F38: WAIFF India x Yotta Data Services — AI Cinema Partnership | G38: N | H38: N | J38: N | K38: N | L38: N | M38: N | O38: Sent | P38: Sent 3 Sep 2026 — Batch 1 (60), Target Batch 2 research.
A39: 2026-09-03 | B39: E2E Networks | C39: Email | D39: sales@e2enetworks.com | F39: WAIFF India x E2E Networks — AI Cinema Partnership | G39: N | H39: N | J39: N | K39: N | L39: N | M39: N | O39: Sent | P39: Sent 3 Sep 2026 — Batch 1 (60), Target Batch 2 research.
A40: 2026-09-03 | B40: Netweb Technologies | C40: Email | D40: mktkol@netwebindia.com | E40: info@netwebindia.com; hydsales@netwebindia.com | F40: WAIFF India x Netweb Technologies — AI Cinema Partnership | G40: N | H40: N | J40: N | K40: N | L40: N | M40: N | O40: Sent | P40: Sent 3 Sep 2026 — Batch 1 (60), Target Batch 2 research.
...

Sheet Sponsor Follow-ups
A1: WAIFF India — Sponsor Follow-ups
A2: Sponsor track only. One row per company: contact, reply status, and the Day 4 / 11 / 25 follow-up cadence (brief section 10). Row 4 is an example — real rows start at row 5.
A3: # | B3: Company | C3: Contact Name | D3: Contact Title | E3: Channel | F3: Date First Contacted | G3: Reply Received? (Y/N) | H3: Reply Date | I3: What They Said | J3: Day 4 Follow-up (Y/N) | K3: Day 11 Follow-up (Y/N) | L3: Day 25 Follow-up (Y/N) | M3: Status | N3: Notes
A4: 0 | B4: Example Co | C4: Jane Doe | D4: Head of Partnerships | E4: Email | F4: 2026-09-03 | G4: N | J4: N | K4: N | L4: N | M4: Sent | N4: EXAMPLE ROW — edit or delete, do not count as real data
A5: 1 | B5: Radisson Blu | E5: Email | F5: 2026-09-01 | G5: Y | H5: 2026-09-03 | I5: Call held 3 Sep. Anuj is interested in the India edition but needs more lucrative/concrete details before he can move it forward internally — guest/talent finalization and similar specifics. He said he will push it to his internal team and MDs. Per Aditya: hold the reply until India-edition details are firmer; keep him warm, do not send a substantive reply yet. | J5: N | K5: N | L5: N | M5: Warm - awaiting more India-edition detail from Aditya before next reply | N5: Sent before this tracker existed — backfilled from Gmail search 3 Sep 2026. Anuj Kumar (Marketing Manager, South Asia) asked 3 specific questions before a call. Replied 3 Sep 2026: covered India edition (Dec 2026, Mumbai), JW Marriott Cannes as existing global sponsor, what Radisson gets (network-wide visibility, access, association) and what WAiFF needs (VIP accommodation/hosting, brand partner role, not just venue). No Canva/deck link sent per standing rule. Asked for a call after 2 PM IST. Awaiting reply.
A6: 2 | B6: EPAM Systems | E6: Email | F6: 2026-09-01 | G6: Y | H6: 2026-09-02 | I6: Suggested speaking after the 9th; looping in colleague Sameena Ali to help set something up. | J6: N | K6: N | L6: N | M6: Awaiting scheduling after 9th | N6: Sent before this tracker existed — backfilled from Gmail search 3 Sep 2026. Nandini Bhatnagar (Sr Director Marketing) wants to talk after Sept 9. Replied 3 Sep 2026 confirming availability anytime after 12:00 PM IST, around 4:00 PM IST or later. Awaiting her scheduling reply.
A7: 3 | B7: Adani Digital Labs | E7: Email | F7: 2026-09-02 | G7: N | J7: N | K7: N | L7: N | M7: Bounced | N7: Sent before this tracker existed — backfilled from Gmail search 3 Sep 2026. BOUNCE: 4 of 8 BCC addresses bounced (cgarg@adanidigitallabs.com, hrishik.jethi@adani.com, manishsingh.payal@adani.com, digitallabs@adani.com)
A8: 4 | B8: Adani AI Labs | E8: Email | F8: 2026-09-02 | G8: N | J8: N | K8: N | L8: N | M8: Bounced | N8: Sent before this tracker existed — backfilled from Gmail search 3 Sep 2026. BOUNCE: 1 of 4 BCC addresses bounced (tanushyam.chattopadhyay@adani.com); also sent separately to Shalini Singh direct
A9: 5 | B9: Freshworks | E9: Email | F9: 2026-09-02 | G9: N | J9: N | K9: N | L9: N | M9: Sent | N9: Sent before this tracker existed — backfilled from Gmail search 3 Sep 2026. Automated support-ticket confirmation only — not a personal reply, no action needed yet
A10: 6 | B10: Zoho | E10: Email | F10: 2026-09-02 | G10: Y | H10: 2026-09-03 | I10: Sales team gave generic product info; partner-operations team pointed to zoho.com/partners as the standard partner program, not a direct sponsorship conversation. | J10: N | K10: N | L10: N | M10: Low priority - generic partner program, not a real lead | N10: Sent before this tracker existed — backfilled from Gmail search 3 Sep 2026. Automated partner-ticket confirmation + generic sales-team reply — not personalized, no action needed yet
A11: 7 | B11: Myntra | E11: Email | F11: 2026-09-02 | G11: N | J11: N | K11: N | L11: N | M11: Bounced | N11: Sent before this tracker existed — backfilled from Gmail search 3 Sep 2026. BOUNCE: Address not found (bounced) — only address used, no BCC alternates
A12: 8 | B12: Tech Mahindra | E12: Email | F12: 2026-09-02 | G12: N | J12: N | K12: N | L12: N | M12: Sent | N12: Sent before this tracker existed — backfilled from Gmail search 3 Sep 2026.
A13: 9 | B13: BenQ India | E13: Email | F13: 2026-09-02 | G13: N | J13: N | K13: N | L13: N | M13: Sent | N13: Sent before this tracker existed — backfilled from Gmail search 3 Sep 2026.
A14: 10 | B14: Sennheiser | E14: Email | F14: 2026-09-02 | G14: N | J14: N | K14: N | L14: N | M14: Sent | N14: Sent before this tracker existed — backfilled from Gmail search 3 Sep 2026.
A15: 11 | B15: Runway | C15: Michelle Kwon | D15: Head of Operations and Partnerships | E15: Email | F15: 2026-09-03 | G15: N | J15: N | K15: N | L15: N | M15: Sent | N15: Sent 3 Sep 2026 — Batch 1 (60), Target Batch 2 research.
A16: 12 | B16: Genmo | C16: Paras Jain | D16: Genmo (title unconfirmed) | E16: Email | F16: 2026-09-03 | G16: N | J16: N | K16: N | L16: N | M16: Sent | N16: Sent 3 Sep 2026 — Batch 1 (60), Target Batch 2 research.
A17: 13 | B17: Shengshu Technology (Vidu) | E17: Email | F17: 2026-09-03 | G17: N | J17: N | K17: N | L17: N | M17: Sent | N17: Sent 3 Sep 2026 — Batch 1 (60), Target Batch 2 research.
A18: 14 | B18: ElevenLabs | E18: Email | F18: 2026-09-03 | G18: N | J18: N | K18: N | L18: N | M18: Sent | N18: Sent 3 Sep 2026 — Batch 1 (60), Target Batch 2 research.
A19: 15 | B19: Murf AI | E19: Email | F19: 2026-09-03 | G19: N | J19: N | K19: N | L19: N | M19: Sent | N19: Sent 3 Sep 2026 — Batch 1 (60), Target Batch 2 research.
A20: 16 | B20: NeuralGarage | E20: Email | F20: 2026-09-03 | G20: N | J20: N | K20: N | L20: N | M20: Sent | N20: Sent 3 Sep 2026 — Batch 1 (60), Target Batch 2 research.
A21: 17 | B21: Synthesia | E21: Email | F21: 2026-09-03 | G21: N | J21: N | K21: N | L21: N | M21: Sent | N21: Sent 3 Sep 2026 — Batch 1 (60), Target Batch 2 research.
A22: 18 | B22: OpusClip (Opus.pro) | E22: Email | F22: 2026-09-03 | G22: N | J22: N | K22: N | L22: N | M22: Sent | N22: Sent 3 Sep 2026 — Batch 1 (60), Target Batch 2 research.
A23: 19 | B23: Captions (Mirage) | E23: Email | F23: 2026-09-03 | G23: N | J23: N | K23: N | L23: N | M23: Sent | N23: Sent 3 Sep 2026 — Batch 1 (60), Target Batch 2 research.
A24: 20 | B24: Topaz Labs | C24: Ross Shain | D24: Principal Creative Technologist | E24: Email | F24: 2026-09-03 | G24: N | J24: N | K24: N | L24: N | M24: Sent | N24: Sent 3 Sep 2026 — Batch 1 (60), Target Batch 2 research.
A25: 21 | B25: Black Forest Labs | E25: Email | F25: 2026-09-03 | G25: N | J25: N | K25: N | L25: N | M25: Sent | N25: Sent 3 Sep 2026 — Batch 1 (60), Target Batch 2 research.
A26: 22 | B26: Stability AI | E26: Email | F26: 2026-09-03 | G26: N | J26: N | K26: N | L26: N | M26: Sent | N26: Sent 3 Sep 2026 — Batch 1 (60), Target Batch 2 research.
A27: 23 | B27: NVIDIA | C27: Parthajit Sar | D27: Marketing programs | E27: Email | F27: 2026-09-03 | G27: Y | H27: 2026-09-03 | I27: Asked for 2025 highlights and public data points before internal review. Replied with verified figures (6,000+ applications/100+ countries 2026, leadership names, global footprint, press coverage), all cross-checked against worldaifilmfestival.com and independent press. | J27: N | K27: N | L27: N | M27: Awaiting internal review, ~2 weeks | N27: Sent 3 Sep 2026 — Batch 1 (60), Target Batch 2 research.
A28: 24 | B28: Qualcomm | C28: Sumit Sonal | D28: Head of Marketing, Qualcomm India | E28: Email | F28: 2026-09-03 | G28: N | J28: N | K28: N | L28: N | M28: Sent | N28: Sent 3 Sep 2026 — Batch 1 (60), Target Batch 2 research.
A29: 25 | B29: Sony India | C29: Nimit Jain | D29: Marketing Communications Head | E29: Email | F29: 2026-09-03 | G29: N | J29: N | K29: N | L29: N | M29: Sent | N29: Sent 3 Sep 2026 — Batch 1 (60), Target Batch 2 research.
A30: 26 | B30: Harman International (JBL) | E30: Email | F30: 2026-09-03 | G30: N | J30: N | K30: N | L30: N | M30: Sent | N30: Sent 3 Sep 2026 — Batch 1 (60), Target Batch 2 research.
A31: 27 | B31: Zebronics | C31: Mansi Sharma | D31: Regional Marketing Manager | E31: Email | F31: 2026-09-03 | G31: N | J31: N | K31: N | L31: N | M31: Sent | N31: Sent 3 Sep 2026 — Batch 1 (60), Target Batch 2 research.
A32: 28 | B32: Dell Technologies India | E32: Email | F32: 2026-09-03 | G32: N | J32: N | K32: N | L32: N | M32: Sent | N32: Sent 3 Sep 2026 — Batch 1 (60), Target Batch 2 research.
A33: 29 | B33: ASUS India | E33: Email | F33: 2026-09-03 | G33: N | J33: N | K33: N | L33: N | M33: Sent | N33: Sent 3 Sep 2026 — Batch 1 (60), Target Batch 2 research.
A34: 30 | B34: Lenovo India | E34: Email | F34: 2026-09-03 | G34: N | J34: N | K34: N | L34: N | M34: Sent | N34: Sent 3 Sep 2026 — Batch 1 (60), Target Batch 2 research.
A35: 31 | B35: Western Digital (SanDisk Professional) | E35: Email | F35: 2026-09-03 | G35: N | J35: N | K35: N | L35: N | M35: Sent | N35: Sent 3 Sep 2026 — Batch 1 (60), Target Batch 2 research.
A36: 32 | B36: Samsung India | C36: Sumit Walia | D36: VP, Head of D2C & Corporate Marketing | E36: Email | F36: 2026-09-03 | G36: N | J36: N | K36: N | L36: N | M36: Sent | N36: Sent 3 Sep 2026 — Batch 1 (60), Target Batch 2 research.
A37: 33 | B37: Krutrim AI (Ola Krutrim) | E37: Email | F37: 2026-09-03 | G37: N | J37: N | K37: N | L37: N | M37: Sent | N37: Sent 3 Sep 2026 — Batch 1 (60), Target Batch 2 research.
A38: 34 | B38: Yotta Data Services | E38: Email | F38: 2026-09-03 | G38: N | J38: N | K38: N | L38: N | M38: Sent | N38: Sent 3 Sep 2026 — Batch 1 (60), Target Batch 2 research.
A39: 35 | B39: E2E Networks | C39: Ashish Dixit | D39: VP Marketing | E39: Email | F39: 2026-09-03 | G39: N | J39: N | K39: N | L39: N | M39: Sent | N39: Sent 3 Sep 2026 — Batch 1 (60), Target Batch 2 research.
A40: 36 | B40: Netweb Technologies | E40: Email | F40: 2026-09-03 | G40: N | J40: N | K40: N | L40: N | M40: Sent | N40: Sent 3 Sep 2026 — Batch 1 (60), Target Batch 2 research.
...

Sheet Organizer Follow-ups
A1: WAIFF India — Organizer Follow-ups
A2: Organizer track only. One row per company: contact, reply status, and the Day 4 / 11 / 25 follow-up cadence (brief section 10). Row 4 is an example — real rows start at row 5.
A3: # | B3: Company | C3: Contact Name | D3: Contact Title | E3: Channel | F3: Date First Contacted | G3: Reply Received? (Y/N) | H3: Reply Date | I3: What They Said | J3: Day 4 Follow-up (Y/N) | K3: Day 11 Follow-up (Y/N) | L3: Day 25 Follow-up (Y/N) | M3: Status | N3: Notes
A4: 0 | B4: Example Co | C4: Jane Doe | D4: Head of Partnerships | E4: Email | F4: 2026-09-03 | G4: N | J4: N | K4: N | L4: N | M4: Sent | N4: EXAMPLE ROW — edit or delete, do not count as real data
A5: 1 | B5: DNEG India | E5: Email | F5: 2026-09-03 | G5: N | J5: N | K5: N | L5: N | M5: Sent | N5: Sent 3 Sep 2026 — Organizer track batch (media/VFX/exhibition pool).
A6: 2 | B6: Red Chillies Entertainment (Redchillies.vfx) | E6: Email | F6: 2026-09-03 | G6: N | J6: N | K6: N | L6: N | M6: Sent | N6: Sent 3 Sep 2026 — Organizer track batch (media/VFX/exhibition pool).
A7: 3 | B7: Applause Entertainment | C7: Prasoon Garg | D7: Chief Business Officer | E7: Email | F7: 2026-09-03 | G7: N | J7: N | K7: N | L7: N | M7: Sent | N7: Sent 3 Sep 2026 — Organizer track batch (media/VFX/exhibition pool).
A8: 4 | B8: Mythri Movie Makers | E8: Email | F8: 2026-09-03 | G8: N | J8: N | K8: N | L8: N | M8: Sent | N8: Sent 3 Sep 2026 — Organizer track batch (media/VFX/exhibition pool).
A9: 5 | B9: Wizcraft International Entertainment | C9: Pratik Shah | D9: Manager, Business Development | E9: Email | F9: 2026-09-03 | G9: N | J9: N | K9: N | L9: N | M9: Sent | N9: Sent 3 Sep 2026 — Organizer track batch (media/VFX/exhibition pool).
A10: 6 | B10: Ramoji Film City | C10: Mohit Chatwal | D10: Director, Sales, Marketing & Operations | E10: Email | F10: 2026-09-03 | G10: N | J10: N | K10: N | L10: N | M10: Sent | N10: Sent 3 Sep 2026 — Organizer track batch (media/VFX/exhibition pool).
A11: 7 | B11: Lyca Productions | E11: Email | F11: 2026-09-03 | G11: N | J11: N | K11: N | L11: N | M11: Sent | N11: Sent 3 Sep 2026 — Organizer track batch (media/VFX/exhibition pool).
A12: 8 | B12: Prime Focus Technologies | C12: T Shobhana | D12: SVP & Global Head of Marketing & Communications | E12: Email | F12: 2026-09-03 | G12: N | J12: N | K12: N | L12: N | M12: Sent | N12: Sent 3 Sep 2026 — Organizer track batch (media/VFX/exhibition pool).
A13: 9 | B13: NY VFXWAALA | C13: Naveen Paul | D13: Founder & Creative Head / Managing Director | E13: Email | F13: 2026-09-03 | G13: N | J13: N | K13: N | L13: N | M13: Sent | N13: Sent 3 Sep 2026 — Organizer track batch (media/VFX/exhibition pool).
A14: 10 | B14: Qube Cinema Technologies | C14: Harshit Thakkar | D14: Director, Products | E14: Email | F14: 2026-09-03 | G14: N | J14: N | K14: N | L14: N | M14: Sent | N14: Sent 3 Sep 2026 — Organizer track batch (media/VFX/exhibition pool).
A15: 11 | B15: Yash Raj Films | C15: Amit Dwivedi | D15: Marketing | E15: Form | F15: 2026-09-03 | G15: N | J15: N | K15: N | L15: N | M15: Draft ready | N15: Business Queries form filled 3 Sep 2026 (Purpose: Brand Partnerships/Talent Management, name, email, address, detailed message referencing Hemant Kundnani's Head of Marketing appointment). Form has a text CAPTCHA - left for Aditya to complete and submit manually, per the no-CAPTCHA-solving rule.
A16: 12 | B16: JioStar (Jio Studios/Reliance Entertainment) | E16: Email | F16: 2026-09-04 | G16: N | J16: N | K16: N | L16: N | M16: Sent
A17: 13 | B17: Zee Entertainment Enterprises | E17: Email | F17: 2026-09-04 | G17: N | J17: N | K17: N | L17: N | M17: Sent
A18: 14 | B18: Dharma Productions | E18: Email | F18: 2026-09-04 | G18: N | J18: N | K18: N | L18: N | M18: Sent
A19: 15 | B19: IIFA (International Indian Film Academy) | E19: Form | F19: 2026-09-04 | G19: N | J19: N | K19: N | L19: N | M19: Sent | N19: Confirmed: "Thank you. Your enquiry has been sent to the IIFA team."
A20: 16 | B20: SonyLIV (Culver Max Entertainment) | E20: Form | F20: 2026-09-06 | G20: N | J20: N | K20: N | L20: N | M20: Draft ready | N20: Relevance: Major Indian OTT platform, natural distribution/organizer angle
A21: 17 | B21: hoichoi | E21: Email | F21: 2026-09-06 | G21: Y | H21: 2026-09-06 | I21: Support inbox auto-replied 3x (once per duplicate send) asking for brand-partnership/collaboration enquiries to go directly to sayantan.guha@hoichoi.tv instead of support@hoichoi.tv. | J21: N | K21: N | L21: N | M21: ACTION NEEDED: send ONE fresh, personalized email to sayantan.guha@hoichoi.tv (do not resend to support@hoichoi.tv) | N21: Relevance: Fast-growing regional OTT platform with a named partnerships routing | AUDIT FINDING (6 Sep Gmail check): this pitch was sent to hoichoi 3 times within ~15 min, and hoichoi auto-replied each time asking to email sayantan.guha@hoichoi.tv directly instead of support@hoichoi.tv. Wrong-channel — needs a fresh, single send to sayantan.guha@hoichoi.tv.
A22: 18 | B22: FTII (Film and Television Institute of India) | E22: Email | F22: 2026-09-06 | G22: N | J22: N | K22: N | L22: N | M22: Sent | N22: Relevance: India's premier film school — a natural jury/masterclass/academic-partner pipeline
A23: 19 | B23: SRFTI (Satyajit Ray Film and Television Institute) | E23: Email | F23: 2026-09-06 | G23: N | J23: N | K23: N | L23: N | M23: Sent | N23: Relevance: Leading Indian film institute with a digital-media specialization closest to AI filmmaking
A24: 20 | B24: T-Hub | E24: Email | F24: 2026-09-06 | G24: N | J24: N | K24: N | L24: N | M24: Sent | N24: Found via 6 Sep Gmail audit (not originally logged this session). India's largest startup incubator/ecosystem body
A25: 21 | B25: Inc42 Media | E25: Email | F25: 2026-09-05 | G25: N | J25: N | K25: N | L25: N | M25: Sent | N25: Found via 6 Sep Gmail audit (not originally logged this session). India's largest tech/startup media platform - potential media partner
A26: 22 | B26: Digital Domain | C26: Sudhir Reddy | D26: President, Global VFX Business | E26: Email | F26: 2026-09-05 | G26: N | J26: N | K26: N | L26: N | M26: Sent | N26: Found via 6 Sep Gmail audit (not originally logged this session). Major VFX studio, new DDAI creative-AI infrastructure
A27: 23 | B27: Weta FX | C27: Daniel Seah | D27: CEO | E27: Email | F27: 2026-09-05 | G27: N | J27: N | K27: N | L27: N | M27: Sent | N27: Found via 6 Sep Gmail audit (not originally logged this session). Premier VFX studio, new AMD AI-rendering partnership
A28: 24 | B28: Framestore | C28: Mel Sullivan | D28: CEO | E28: Email | F28: 2026-09-05 | G28: N | J28: N | K28: N | L28: N | M28: Sent | N28: Found via 6 Sep Gmail audit (not originally logged this session). Major VFX studio, 15 VES Award nominations
A29: 25 | B29: Industrial Light & Magic (ILM) | E29: Email | F29: 2026-09-05 | G29: N | J29: N | K29: N | L29: N | M29: Sent | N29: Found via 6 Sep Gmail audit (not originally logged this session). Legendary VFX studio (Lucasfilm)
A30: 26 | B30: MPC (Moving Picture Company) | E30: Email | F30: 2026-09-05 | G30: N | J30: N | K30: N | L30: N | M30: Sent | N30: Found via 6 Sep Gmail audit (not originally logged this session). Major VFX studio, named contact
A31: 27 | B31: Excel Entertainment | C31: Vishal Ramchandani | D31: CEO | E31: Email | F31: 2026-09-05 | G31: N | J31: N | K31: N | L31: N | M31: Sent | N31: Found via 6 Sep Gmail audit (not originally logged this session). Major Bollywood production house, new-talent-backing mission (Excel Origins)
A32: 28 | B32: Miraj Entertainment (Cinemas) | E32: Email | F32: 2026-09-05 | G32: N | J32: N | K32: N | L32: N | M32: Sent | N32: Found via 6 Sep Gmail audit (not originally logged this session). Fast-expanding Indian multiplex chain
A33: 29 | B33: Anibrain | C33: Jesh Krishna Murthy | D33: Founder & CEO | E33: Email | F33: 2026-09-05 | G33: N | J33: N | K33: N | L33: N | M33: Sent | N33: Found via 6 Sep Gmail audit (not originally logged this session). Indian VFX/animation studio with international credits
A34: 30 | B34: Cinepolis India | C34: Amit Garg | D34: Head of Business Development | E34: Email | F34: 2026-09-05 | G34: N | J34: N | K34: N | L34: N | M34: Sent | N34: Found via 6 Sep Gmail audit (not originally logged this session). Major multiplex chain, 489 screens/41 cities
A35: 31 | B35: Abundantia Entertainment | E35: Email | F35: 2026-09-03 | G35: N | J35: N | K35: N | L35: N | M35: Sent | N35: Found via 6 Sep Gmail audit (not originally logged this session). LinkedIn-sourced contact (Vikram Malhotra) - connected on LinkedIn first, then emailed. Major Indian production house.

Sheet Replies Tracker
A1: WAIFF India — Replies Tracker
A2: Only real, relevant replies go here (not auto-acknowledgements). One row per reply. Track: name of person, company, track, what they said, and what's needed next.
A3: Date | B3: Company | C3: Person Name | D3: Track (Sponsor/Organizer/Existing) | E3: Reply Type | F3: What they said | G3: Follow-up needed | H3: Follow-up sent date | I3: Status
A4: 2026-09-03 | B4: Radisson Blu | C4: Anuj Kumar | D4: Existing (live client) | E4: Real reply - call held | F4: Call held 3 Sep. Anuj is interested in the India edition but needs more lucrative/concrete details before he can move it forward internally — guest/talent finalization and similar specifics. He said he will push it to his internal team and MDs. Per Aditya: hold the reply until India-edition details are firmer; keep him warm, do not send a substantive reply yet. | G4: N (holding per Aditya) | H4: 2026-09-03 | I4: Warm - awaiting more India-edition detail from Aditya before next reply
A5: 2026-09-02 | B5: EPAM Systems | C5: Nandini Bhatnagar (Sr. Director Marketing) | D5: Existing (live client) | E5: Real reply | F5: Suggested speaking after the 9th; looping in colleague Sameena Ali to help set something up. | G5: Y | H5: 2026-09-03 | I5: Awaiting scheduling after 9th
A6: 2026-09-03 | B6: NVIDIA | C6: Shristi Mahnot (India Enterprise PR Manager) | D6: Sponsor | E6: Real reply - decline then referral | F6: Declined sponsorship directly (PR does not handle it), then looped in colleague Kavita Aroor for ecosystem/developer-relations angle. | G6: Y | H6: 2026-09-03 | I6: Awaiting Kavita's reply
A7: 2026-09-03 | B7: Zoho | C7: Partner Operations team | D7: Sponsor | E7: Auto-routed to partner program | F7: Sales team gave generic product info; partner-operations team pointed to zoho.com/partners as the standard partner program, not a direct sponsorship conversation. | G7: N | I7: Low priority - generic partner program, not a real lead
A8: 2026-09-03 | B8: Vidu (Shengshu Technology) | C8: support team | D8: Sponsor | E8: Automated acknowledgement | F8: Generic thank-you, said team will follow up if there's a collaboration opportunity. | G8: N | I8: Wait and see
A9: 2026-09-03 | B9: Nikon (RED Digital Cinema) | C9: NIND Support | D9: Sponsor | E9: Automated acknowledgement | F9: Said details shared with the respective team for review. | G9: N | I9: Wait and see
A10: 2026-09-03 | B10: NVIDIA | C10: Kavita Aroor (Head Enterprise & Developer Marketing, South Asia) | D10: Sponsor | E10: Real reply - data request | F10: Asked for 2025 highlights and public data points before internal review. Replied with verified figures (6,000+ applications/100+ countries 2026, leadership names, global footprint, press coverage), all cross-checked against worldaifilmfestival.com and independent press. | G10: Y | H10: 2026-09-03 | I10: Awaiting internal review, ~2 weeks
